Workbook

Sheet Plantilla
A1: Prueba | B1: Subsistema | C1: Pyphi | F1: Proyecto (Pro) | I1: Proyecto Paralelo MP | L1: Proyecto Paralelo CUDA | O1: Comparacion
C2: Particion | D2: Perdida Phi | E2: Tiempo Phi | F2: Particion | G2: Perdida Pro | H2: Tiempo Pro | I2: Particion | J2: Perdida MP | K2: Tiempo MP | L2: Particion | M2: Perdida CUDA | N2: Tiempo CUDA | O2: % Perdida Pro | P2: % Perdida MP | Q2: % Perdida CUDA | R2: SpeedUp Pro (X) | S2: SpeedUp MP (X) | T2: SpeedUp CUDA (X)
A3: 1 | O3: =ABS(D3-G3)/IF(D3=0,1,D3) -> 0 | P3: =ABS(D3-J3)/IF(D3=0,1,D3) -> 0 | Q3: =ABS(D3-M3)/IF(D3=0,1,D3) -> 0 | R3: =ROUND(IF(E3<H3, -(H3/IF(E3=0,1,E3)), IF(E3=0,1,E3)/IF(H3=0,1,H3)), 2) -> 1 | S3: =ROUND(IF(H3<K3, -(K3/IF(H3=0,1,H3)), IF(H3=0,1,H3)/IF(K3=0,1,K3)), 2) -> 1 | T3: =ROUND(IF(H3<N3, -(N3/IF(H3=0,1,H3)), IF(H3=0,1,H3)/IF(N3=0,1,N3)), 2) -> 1
A4: 2 | O4: =ABS(D4-G4)/IF(D4=0,1,D4) -> 0 | P4: =ABS(D4-J4)/IF(D4=0,1,D4) -> 0 | Q4: =ABS(D4-M4)/IF(D4=0,1,D4) -> 0 | R4: =ROUND(IF(E4<H4, -(H4/IF(E4=0,1,E4)), IF(E4=0,1,E4)/IF(H4=0,1,H4)), 2) -> 1 | S4: =ROUND(IF(H4<K4, -(K4/IF(H4=0,1,H4)), IF(H4=0,1,H4)/IF(K4=0,1,K4)), 2) -> 1 | T4: =ROUND(IF(H4<N4, -(N4/IF(H4=0,1,H4)), IF(H4=0,1,H4)/IF(N4=0,1,N4)), 2) -> 1
A5: 3 | O5: =ABS(D5-G5)/IF(D5=0,1,D5) -> 0 | P5: =ABS(D5-J5)/IF(D5=0,1,D5) -> 0 | Q5: =ABS(D5-M5)/IF(D5=0,1,D5) -> 0 | R5: =ROUND(IF(E5<H5, -(H5/IF(E5=0,1,E5)), IF(E5=0,1,E5)/IF(H5=0,1,H5)), 2) -> 1 | S5: =ROUND(IF(H5<K5, -(K5/IF(H5=0,1,H5)), IF(H5=0,1,H5)/IF(K5=0,1,K5)), 2) -> 1 | T5: =ROUND(IF(H5<N5, -(N5/IF(H5=0,1,H5)), IF(H5=0,1,H5)/IF(N5=0,1,N5)), 2) -> 1
A6: 4 | O6: =ABS(D6-G6)/IF(D6=0,1,D6) -> 0 | P6: =ABS(D6-J6)/IF(D6=0,1,D6) -> 0 | Q6: =ABS(D6-M6)/IF(D6=0,1,D6) -> 0 | R6: =ROUND(IF(E6<H6, -(H6/IF(E6=0,1,E6)), IF(E6=0,1,E6)/IF(H6=0,1,H6)), 2) -> 1 | S6: =ROUND(IF(H6<K6, -(K6/IF(H6=0,1,H6)), IF(H6=0,1,H6)/IF(K6=0,1,K6)), 2) -> 1 | T6: =ROUND(IF(H6<N6, -(N6/IF(H6=0,1,H6)), IF(H6=0,1,H6)/IF(N6=0,1,N6)), 2) -> 1
A7: 5 | O7: =ABS(D7-G7)/IF(D7=0,1,D7) -> 0 | P7: =ABS(D7-J7)/IF(D7=0,1,D7) -> 0 | Q7: =ABS(D7-M7)/IF(D7=0,1,D7) -> 0 | R7: =ROUND(IF(E7<H7, -(H7/IF(E7=0,1,E7)), IF(E7=0,1,E7)/IF(H7=0,1,H7)), 2) -> 1 | S7: =ROUND(IF(H7<K7, -(K7/IF(H7=0,1,H7)), IF(H7=0,1,H7)/IF(K7=0,1,K7)), 2) -> 1 | T7: =ROUND(IF(H7<N7, -(N7/IF(H7=0,1,H7)), IF(H7=0,1,H7)/IF(N7=0,1,N7)), 2) -> 1
A8: 6 | O8: =ABS(D8-G8)/IF(D8=0,1,D8) -> 0 | P8: =ABS(D8-J8)/IF(D8=0,1,D8) -> 0 | Q8: =ABS(D8-M8)/IF(D8=0,1,D8) -> 0 | R8: =ROUND(IF(E8<H8, -(H8/IF(E8=0,1,E8)), IF(E8=0,1,E8)/IF(H8=0,1,H8)), 2) -> 1 | S8: =ROUND(IF(H8<K8, -(K8/IF(H8=0,1,H8)), IF(H8=0,1,H8)/IF(K8=0,1,K8)), 2) -> 1 | T8: =ROUND(IF(H8<N8, -(N8/IF(H8=0,1,H8)), IF(H8=0,1,H8)/IF(N8=0,1,N8)), 2) -> 1
A9: 7 | O9: =ABS(D9-G9)/IF(D9=0,1,D9) -> 0 | P9: =ABS(D9-J9)/IF(D9=0,1,D9) -> 0 | Q9: =ABS(D9-M9)/IF(D9=0,1,D9) -> 0 | R9: =ROUND(IF(E9<H9, -(H9/IF(E9=0,1,E9)), IF(E9=0,1,E9)/IF(H9=0,1,H9)), 2) -> 1 | S9: =ROUND(IF(H9<K9, -(K9/IF(H9=0,1,H9)), IF(H9=0,1,H9)/IF(K9=0,1,K9)), 2) -> 1 | T9: =ROUND(IF(H9<N9, -(N9/IF(H9=0,1,H9)), IF(H9=0,1,H9)/IF(N9=0,1,N9)), 2) -> 1
A10: 8 | O10: =ABS(D10-G10)/IF(D10=0,1,D10) -> 0 | P10: =ABS(D10-J10)/IF(D10=0,1,D10) -> 0 | Q10: =ABS(D10-M10)/IF(D10=0,1,D10) -> 0 | R10: =ROUND(IF(E10<H10, -(H10/IF(E10=0,1,E10)), IF(E10=0,1,E10)/IF(H10=0,1,H10)), 2) -> 1 | S10: =ROUND(IF(H10<K10, -(K10/IF(H10=0,1,H10)), IF(H10=0,1,H10)/IF(K10=0,1,K10)), 2) -> 1 | T10: =ROUND(IF(H10<N10, -(N10/IF(H10=0,1,H10)), IF(H10=0,1,H10)/IF(N10=0,1,N10)), 2) -> 1
A11: 9 | O11: =ABS(D11-G11)/IF(D11=0,1,D11) -> 0 | P11: =ABS(D11-J11)/IF(D11=0,1,D11) -> 0 | Q11: =ABS(D11-M11)/IF(D11=0,1,D11) -> 0 | R11: =ROUND(IF(E11<H11, -(H11/IF(E11=0,1,E11)), IF(E11=0,1,E11)/IF(H11=0,1,H11)), 2) -> 1 | S11: =ROUND(IF(H11<K11, -(K11/IF(H11=0,1,H11)), IF(H11=0,1,H11)/IF(K11=0,1,K11)), 2) -> 1 | T11: =ROUND(IF(H11<N11, -(N11/IF(H11=0,1,H11)), IF(H11=0,1,H11)/IF(N11=0,1,N11)), 2) -> 1
A12: 10 | O12: =ABS(D12-G12)/IF(D12=0,1,D12) -> 0 | P12: =ABS(D12-J12)/IF(D12=0,1,D12) -> 0 | Q12: =ABS(D12-M12)/IF(D12=0,1,D12) -> 0 | R12: =ROUND(IF(E12<H12, -(H12/IF(E12=0,1,E12)), IF(E12=0,1,E12)/IF(H12=0,1,H12)), 2) -> 1 | S12: =ROUND(IF(H12<K12, -(K12/IF(H12=0,1,H12)), IF(H12=0,1,H12)/IF(K12=0,1,K12)), 2) -> 1 | T12: =ROUND(IF(H12<N12, -(N12/IF(H12=0,1,H12)), IF(H12=0,1,H12)/IF(N12=0,1,N12)), 2) -> 1
A13: 11 | O13: =ABS(D13-G13)/IF(D13=0,1,D13) -> 0 | P13: =ABS(D13-J13)/IF(D13=0,1,D13) -> 0 | Q13: =ABS(D13-M13)/IF(D13=0,1,D13) -> 0 | R13: =ROUND(IF(E13<H13, -(H13/IF(E13=0,1,E13)), IF(E13=0,1,E13)/IF(H13=0,1,H13)), 2) -> 1 | S13: =ROUND(IF(H13<K13, -(K13/IF(H13=0,1,H13)), IF(H13=0,1,H13)/IF(K13=0,1,K13)), 2) -> 1 | T13: =ROUND(IF(H13<N13, -(N13/IF(H13=0,1,H13)), IF(H13=0,1,H13)/IF(N13=0,1,N13)), 2) -> 1
A14: 12 | O14: =ABS(D14-G14)/IF(D14=0,1,D14) -> 0 | P14: =ABS(D14-J14)/IF(D14=0,1,D14) -> 0 | Q14: =ABS(D14-M14)/IF(D14=0,1,D14) -> 0 | R14: =ROUND(IF(E14<H14, -(H14/IF(E14=0,1,E14)), IF(E14=0,1,E14)/IF(H14=0,1,H14)), 2) -> 1 | S14: =ROUND(IF(H14<K14, -(K14/IF(H14=0,1,H14)), IF(H14=0,1,H14)/IF(K14=0,1,K14)), 2) -> 1 | T14: =ROUND(IF(H14<N14, -(N14/IF(H14=0,1,H14)), IF(H14=0,1,H14)/IF(N14=0,1,N14)), 2) -> 1
... A52: 50 | O52: =ABS(D52-G52)/IF(D52=0,1,D52) -> 0 | P52: =ABS(D52-J52)/IF(D52=0,1,D52) -> 0 | Q52: =ABS(D52-M52)/IF(D52=0,1,D52) -> 0 | R52: =ROUND(IF(E52<H52, -(H52/IF(E52=0,1,E52)), IF(E52=0,1,E52)/IF(H52=0,1,H52)), 2) -> 1 | S52: =ROUND(IF(H52<K52, -(K52/IF(H52=0,1,H52)), IF(H52=0,1,H52)/IF(K52=0,1,K52)), 2) -> 1 | T52: =ROUND(IF(H52<N52, -(N52/IF(H52=0,1,H52)), IF(H52=0,1,H52)/IF(N52=0,1,N52)), 2) -> 1
I53: PROMEDIO | O53: =AVERAGE(O$3:O$52) -> 0 | P53: =AVERAGE(P$3:P$52) -> 0 | Q53: =AVERAGE(Q$3:Q$52) -> 0 | R53: =AVERAGE(R$3:R$52) -> 1 | S53: =AVERAGE(S$3:S$52) -> 1 | T53: =AVERAGE(T$3:T$52) -> 1
I54: MINIMO | O54: =MIN(O$3:O$52) -> 0 | P54: =MIN(P$3:P$52) -> 0 | Q54: =MIN(Q$3:Q$52) -> 0 | R54: =MIN(R$3:R$52) -> 1 | S54: =MIN(S$3:S$52) -> 1 | T54: =MIN(T$3:T$52) -> 1
I55: MAXIMO | O55: =MAX(O$3:O$52) -> 0 | P55: =MAX(P$3:P$52) -> 0 | Q55: =MAX(Q$3:Q$52) -> 0 | R55: =MAX(R$3:R$52) -> 1 | S55: =MAX(S$3:S$52) -> 1 | T55: =MAX(T$3:T$52) -> 1
O56: % Perdida Pro | P56: % Perdida MP | Q56: % Perdida CUDA | R56: SpeedUp Pro (X) | S56: SpeedUp MP (X) | T56: SpeedUp CUDA (X)

Sheet 3 Elementos
A1: Prueba | B1: Subsistema | C1: Pyphi | F1: Proyecto (Pro) | I1: Proyecto Paralelo MP | L1: Comparacion
C2: Particion | D2: Perdida Phi | E2: Tiempo Phi | F2: Particion | G2: Perdida Pro | H2: Tiempo Pro | I2: Particion | J2: Perdida MP | K2: Tiempo MP | L2: % Perdida Pro | M2: % Perdida MP | N2: SpeedUp Pro (X) | O2: SpeedUp MP (X)
A3: 1 | B3: ABC_{t+1}|ABC_{t} | C3: ⎛ B ⎞⎛ A,C ⎞_x000D_ ⎝ ∅ ⎠⎝ a,b,c ⎠_x000D_ | D3: 0.25 | E3: 0.01 | F3: ⎛ B ⎞⎛ A,C ⎞_x000D_ ⎝ ∅ ⎠⎝ a,b,c ⎠_x000D_ | G3: 0.25 | H3: 0 | I3: ⎛ B ⎞⎛ A,C ⎞_x000D_ ⎝ ∅ ⎠⎝ a,b,c ⎠_x000D_ | J3: 0.25 | K3: 11.84 | L3: =ABS(D3-G3)/IF(D3=0,1,D3) -> 0 | M3: =ABS(D3-J3)/IF(D3=0,1,D3) -> 0 | N3: =ROUND(IF(E3<H3, -(H3/IF(E3=0,1,E3)), IF(E3=0,1,E3)/IF(H3=0,1,H3)), 2) -> 0.01 | O3: =ROUND(IF(H3<K3, -(K3/IF(H3=0,1,H3)), IF(H3=0,1,H3)/IF(K3=0,1,K3)), 2) -> -11.84
A4: 2 | B4: ABC_{t+1}|AB_{t} | C4: ⎛ A ⎞⎛ B,C ⎞_x000D_ ⎝ ∅ ⎠⎝ a,b ⎠_x000D_ | D4: 0.25 | E4: 0 | F4: ⎛ A ⎞⎛ B,C ⎞_x000D_ ⎝ ∅ ⎠⎝ a,b ⎠_x000D_ | G4: 0.25 | H4: 0 | I4: ⎛ A ⎞⎛ B,C ⎞_x000D_ ⎝ ∅ ⎠⎝ a,b ⎠_x000D_ | J4: 0.25 | K4: 11.44 | L4: =ABS(D4-G4)/IF(D4=0,1,D4) -> 0 | M4: =ABS(D4-J4)/IF(D4=0,1,D4) -> 0 | N4: =ROUND(IF(E4<H4, -(H4/IF(E4=0,1,E4)), IF(E4=0,1,E4)/IF(H4=0,1,H4)), 2) -> 1 | O4: =ROUND(IF(H4<K4, -(K4/IF(H4=0,1,H4)), IF(H4=0,1,H4)/IF(K4=0,1,K4)), 2) -> -11.44
A5: 3 | B5: ABC_{t+1}|BC_{t} | C5: ⎛ C ⎞⎛ A,B ⎞_x000D_ ⎝ ∅ ⎠⎝ b,c ⎠_x000D_ | D5: 0 | E5: 0 | F5: ⎛ C ⎞⎛ A,B ⎞_x000D_ ⎝ ∅ ⎠⎝ b,c ⎠_x000D_ | G5: 0 | H5: 0 | I5: ⎛ C ⎞⎛ A,B ⎞_x000D_ ⎝ ∅ ⎠⎝ b,c ⎠_x000D_ | J5: 0 | K5: 10.95 | L5: =ABS(D5-G5)/IF(D5=0,1,D5) -> 0 | M5: =ABS(D5-J5)/IF(D5=0,1,D5) -> 0 | N5: =ROUND(IF(E5<H5, -(H5/IF(E5=0,1,E5)), IF(E5=0,1,E5)/IF(H5=0,1,H5)), 2) -> 1 | O5: =ROUND(IF(H5<K5, -(K5/IF(H5=0,1,H5)), IF(H5=0,1,H5)/IF(K5=0,1,K5)), 2) -> -10.95
A6: 4 | B6: ABC_{t+1}|B_{t} | C6: ⎛ B ⎞⎛ A,C ⎞_x000D_ ⎝ ∅ ⎠⎝ b ⎠_x000D_ | D6: 0 | E6: 0.01 | F6: ⎛ B,C ⎞⎛ A ⎞_x000D_ ⎝ ∅ ⎠⎝ b ⎠_x000D_ | G6: 0 | H6: 0 | I6: ⎛ B,C ⎞⎛ A ⎞_x000D_ ⎝ ∅ ⎠⎝ b ⎠_x000D_ | J6: 0 | K6: 11.03 | L6: =ABS(D6-G6)/IF(D6=0,1,D6) -> 0 | M6: =ABS(D6-J6)/IF(D6=0,1,D6) -> 0 | N6: =ROUND(IF(E6<H6, -(H6/IF(E6=0,1,E6)), IF(E6=0,1,E6)/IF(H6=0,1,H6)), 2) -> 0.01 | O6: =ROUND(IF(H6<K6, -(K6/IF(H6=0,1,H6)), IF(H6=0,1,H6)/IF(K6=0,1,K6)), 2) -> -11.03
A7: 5 | B7: ABC_{t+1}|AC_{t} | C7: ⎛ C ⎞⎛ A,B ⎞_x000D_ ⎝ ∅ ⎠⎝ a,c ⎠_x000D_ | D7: 0 | E7: 0.02 | F7: ⎛ C ⎞⎛ A,B ⎞_x000D_ ⎝ ∅ ⎠⎝ a,c ⎠_x000D_ | G7: 0 | H7: 0 | I7: ⎛ C ⎞⎛ A,B ⎞_x000D_ ⎝ ∅ ⎠⎝ a,c ⎠_x000D_ | J7: 0 | K7: 10.86 | L7: =ABS(D7-G7)/IF(D7=0,1,D7) -> 0 | M7: =ABS(D7-J7)/IF(D7=0,1,D7) -> 0 | N7: =ROUND(IF(E7<H7, -(H7/IF(E7=0,1,E7)), IF(E7=0,1,E7)/IF(H7=0,1,H7)), 2) -> 0.02 | O7: =ROUND(IF(H7<K7, -(K7/IF(H7=0,1,H7)), IF(H7=0,1,H7)/IF(K7=0,1,K7)), 2) -> -10.86
A8: 6 | B8: ABC_{t+1}|B_{t} | C8: ⎛ B ⎞⎛ A,C ⎞_x000D_ ⎝ ∅ ⎠⎝ b ⎠_x000D_ | D8: 0 | E8: 0.06 | F8: ⎛ B,C ⎞⎛ A ⎞_x000D_ ⎝ ∅ ⎠⎝ b ⎠_x000D_ | G8: 0 | H8: 0 | I8: ⎛ B,C ⎞⎛ A ⎞_x000D_ ⎝ ∅ ⎠⎝ b ⎠_x000D_ | J8: 0 | K8: 11.07 | L8: =ABS(D8-G8)/IF(D8=0,1,D8) -> 0 | M8: =ABS(D8-J8)/IF(D8=0,1,D8) -> 0 | N8: =ROUND(IF(E8<H8, -(H8/IF(E8=0,1,E8)), IF(E8=0,1,E8)/IF(H8=0,1,H8)), 2) -> 0.06 | O8: =ROUND(IF(H8<K8, -(K8/IF(H8=0,1,H8)), IF(H8=0,1,H8)/IF(K8=0,1,K8)), 2) -> -11.07
A9: 7 | B9: ABC_{t+1}|AB_{t} | C9: ⎛ A ⎞⎛ B,C ⎞_x000D_ ⎝ ∅ ⎠⎝ a,b ⎠_x000D_ | D9: 0.25 | E9: 0.21 | F9: ⎛ A ⎞⎛ B,C ⎞_x000D_ ⎝ ∅ ⎠⎝ a,b ⎠_x000D_ | G9: 0.25 | H9: 0 | I9: ⎛ A ⎞⎛ B,C ⎞_x000D_ ⎝ ∅ ⎠⎝ a,b ⎠_x000D_ | J9: 0.25 | K9: 10.84 | L9: =ABS(D9-G9)/IF(D9=0,1,D9) -> 0 | M9: =ABS(D9-J9)/IF(D9=0,1,D9) -> 0 | N9: =ROUND(IF(E9<H9, -(H9/IF(E9=0,1,E9)), IF(E9=0,1,E9)/IF(H9=0,1,H9)), 2) -> 0.21 | O9: =ROUND(IF(H9<K9, -(K9/IF(H9=0,1,H9)), IF(H9=0,1,H9)/IF(K9=0,1,K9)), 2) -> -10.84
A10: 8 | B10: AB_{t+1}|ABC_{t} | C10: ⎛ ∅ ⎞⎛ A,B ⎞_x000D_ ⎝ a ⎠⎝ b,c ⎠_x000D_ | D10: 0 | E10: 0 | F10: ⎛ B ⎞⎛ A ⎞_x000D_ ⎝ ∅ ⎠⎝ a,b,c ⎠_x000D_ | G10: 0.25 | H10: 0 | I10: ⎛ B ⎞⎛ A ⎞_x000D_ ⎝ ∅ ⎠⎝ a,b,c ⎠_x000D_ | J10: 0.25 | K10: 10.84 | L10: =ABS(D10-G10)/IF(D10=0,1,D10) -> 0.25 | M10: =ABS(D10-J10)/IF(D10=0,1,D10) -> 0.25 | N10: =ROUND(IF(E10<H10, -(H10/IF(E10=0,1,E10)), IF(E10=0,1,E10)/IF(H10=0,1,H10)), 2) -> 1 | O10: =ROUND(IF(H10<K10, -(K10/IF(H10=0,1,H10)), IF(H10=0,1,H10)/IF(K10=0,1,K10)), 2) -> -10.84
A11: 9 | B11: AB_{t+1}|AB_{t} | C11: ⎛ B ⎞⎛ A ⎞_x000D_ ⎝ a ⎠⎝ b ⎠_x000D_ | D11: 0 | E11: 0 | F11: ⎛ A ⎞⎛ B ⎞_x000D_ ⎝ ∅ ⎠⎝ a,b ⎠_x000D_ | G11: 0.25 | H11: 0 | I11: ⎛ A ⎞⎛ B ⎞_x000D_ ⎝ ∅ ⎠⎝ a,b ⎠_x000D_ | J11: 0.25 | K11: 10.98 | L11: =ABS(D11-G11)/IF(D11=0,1,D11) -> 0.25 | M11: =ABS(D11-J11)/IF(D11=0,1,D11) -> 0.25 | N11: =ROUND(IF(E11<H11, -(H11/IF(E11=0,1,E11)), IF(E11=0,1,E11)/IF(H11=0,1,H11)), 2) -> 1 | O11: =ROUND(IF(H11<K11, -(K11/IF(H11=0,1,H11)), IF(H11=0,1,H11)/IF(K11=0,1,K11)), 2) -> -10.98
A12: 10 | B12: AB_{t+1}|BC_{t} | C12: ⎛ B ⎞⎛ A ⎞_x000D_ ⎝ ∅ ⎠⎝ b,c ⎠_x000D_ | D12: 0.25 | E12: 0 | F12: ⎛ B ⎞⎛ A ⎞_x000D_ ⎝ ∅ ⎠⎝ b,c ⎠_x000D_ | G12: 0.25 | H12: 0 | I12: ⎛ B ⎞⎛ A ⎞_x000D_ ⎝ ∅ ⎠⎝ b,c ⎠_x000D_ | J12: 0.25 | K12: 11.04 | L12: =ABS(D12-G12)/IF(D12=0,1,D12) -> 0 | M12: =ABS(D12-J12)/IF(D12=0,1,D12) -> 0 | N12: =ROUND(IF(E12<H12, -(H12/IF(E12=0,1,E12)), IF(E12=0,1,E12)/IF(H12=0,1,H12)), 2) -> 1 | O12: =ROUND(IF(H12<K12, -(K12/IF(H12=0,1,H12)), IF(H12=0,1,H12)/IF(K12=0,1,K12)), 2) -> -11.04
A13: 11 | B13: AB_{t+1}|B_{t} | C13: ⎛ B ⎞⎛ A ⎞_x000D_ ⎝ ∅ ⎠⎝ b ⎠_x000D_ | D13: 0 | E13: 0.01 | F13: ⎛ B ⎞⎛ A ⎞_x000D_ ⎝ ∅ ⎠⎝ b ⎠_x000D_ | G13: 0 | H13: 0 | I13: ⎛ B ⎞⎛ A ⎞_x000D_ ⎝ ∅ ⎠⎝ b ⎠_x000D_ | J13: 0 | K13: 10.89 | L13: =ABS(D13-G13)/IF(D13=0,1,D13) -> 0 | M13: =ABS(D13-J13)/IF(D13=0,1,D13) -> 0 | N13: =ROUND(IF(E13<H13, -(H13/IF(E13=0,1,E13)), IF(E13=0,1,E13)/IF(H13=0,1,H13)), 2) -> 0.01 | O13: =ROUND(IF(H13<K13, -(K13/IF(H13=0,1,H13)), IF(H13=0,1,H13)/IF(K13=0,1,K13)), 2) -> -10.89
A14: 12 | B14: AB_{t+1}|AC_{t} | C14: ⎛ ∅ ⎞⎛ A,B ⎞_x000D_ ⎝ a ⎠⎝ c ⎠_x000D_ | D14: 0 | E14: 0.02 | F14: ⎛ A ⎞⎛ B ⎞_x000D_ ⎝ a ⎠⎝ c ⎠_x000D_ | G14: 0.25 | H14: 0 | I14: ⎛ A ⎞⎛ B ⎞_x000D_ ⎝ a ⎠⎝ c ⎠_x000D_ | J14: 0.25 | K14: 10.82 | L14: =ABS(D14-G14)/IF(D14=0,1,D14) -> 0.25 | M14: =ABS(D14-J14)/IF(D14=0,1,D14) -> 0.25 | N14: =ROUND(IF(E14<H14, -(H14/IF(E14=0,1,E14)), IF(E14=0,1,E14)/IF(H14=0,1,H14)), 2) -> 0.02 | O14: =ROUND(IF(H14<K14, -(K14/IF(H14=0,1,H14)), IF(H14=0,1,H14)/IF(K14=0,1,K14)), 2) -> -10.82
... A51: 49 | B51: AB_{t+1}|AB_{t} | C51: ⎛ B ⎞⎛ A ⎞_x000D_ ⎝ a ⎠⎝ b ⎠_x000D_ | D51: 0 | E51: 0.19 | F51: ⎛ A ⎞⎛ B ⎞_x000D_ ⎝ ∅ ⎠⎝ a,b ⎠_x000D_ | G51: 0.25 | H51: 0 | I51: ⎛ A ⎞⎛ B ⎞_x000D_ ⎝ ∅ ⎠⎝ a,b ⎠_x000D_ | J51: 0.25 | K51: 12.08 | L51: =ABS(D51-G51)/IF(D51=0,1,D51) -> 0.25 | M51: =ABS(D51-J51)/IF(D51=0,1,D51) -> 0.25 | N51: =ROUND(IF(E51<H51, -(H51/IF(E51=0,1,E51)), IF(E51=0,1,E51)/IF(H51=0,1,H51)), 2) -> 0.19 | O51: =ROUND(IF(H51<K51, -(K51/IF(H51=0,1,H51)), IF(H51=0,1,H51)/IF(K51=0,1,K51)), 2) -> -12.08
I52: PROMEDIO | L52: =AVERAGE(L$3:L$51) -> 0.076530612 | M52: =AVERAGE(M$3:M$51) -> 0.076530612 | N52: =AVERAGE(N$3:N$51) -> 0.4877551 | O52: =AVERAGE(O$3:O$51) -> -11.463265
I53: MINIMO | L53: =MIN(L$3:L$51) -> 0 | M53: =MIN(M$3:M$51) -> 0 | N53: =MIN(N$3:N$51) -> 0.01 | O53: =MIN(O$3:O$51) -> -15.94
I54: MAXIMO | L54: =MAX(L$3:L$51) -> 0.25 | M54: =MAX(M$3:M$51) -> 0.25 | N54: =MAX(N$3:N$51) -> 1 | O54: =MAX(O$3:O$51) -> -10.66
L55: % Perdida Pro | M55: % Perdida MP | N55: SpeedUp Pro (X) | O55: SpeedUp MP (X)

Sheet 5 Elementos
A1: Prueba | B1: Subsistema | C1: Pyphi | F1: Proyecto (Pro) | I1: Proyecto Paralelo MP | L1: Comparacion
C2: Particion | D2: Perdida Phi | E2: Tiempo Phi | F2: Particion | G2: Perdida Pro | H2: Tiempo Pro | I2: Particion | J2: Perdida MP | K2: Tiempo MP | L2: % Perdida Pro | M2: % Perdida MP | N2: SpeedUp Pro (X) | O2: SpeedUp MP (X)
A3: 1 | B3: ABCDE_{t+1}|ABCDE_{t} | C3: ⎛ D ⎞⎛ A,B,C,E ⎞_x000D_ ⎝ ∅ ⎠⎝ a,b,c,d,e ⎠_x000D_ | D3: 0 | E3: 0 | F3: ⎛ D ⎞⎛ A,B,C,E ⎞_x000D_ ⎝ ∅ ⎠⎝ a,b,c,d,e ⎠_x000D_ | G3: 0 | H3: 0.01 | I3: ⎛ D ⎞⎛ A,B,C,E ⎞_x000D_ ⎝ ∅ ⎠⎝ a,b,c,d,e ⎠_x000D_ | J3: 0 | K3: 14.75 | L3: =ABS(D3-G3)/IF(D3=0,1,D3) -> 0 | M3: =ABS(D3-J3)/IF(D3=0,1,D3) -> 0 | N3: =ROUND(IF(E3<H3, -(H3/IF(E3=0,1,E3)), IF(E3=0,1,E3)/IF(H3=0,1,H3)), 2) -> -0.01 | O3: =ROUND(IF(H3<K3, -(K3/IF(H3=0,1,H3)), IF(H3=0,1,H3)/IF(K3=0,1,K3)), 2) -> -1475
A4: 2 | B4: ABCDE_{t+1}|ABCD_{t} | C4: ⎛ D ⎞⎛ A,B,C,E ⎞_x000D_ ⎝ ∅ ⎠⎝ a,b,c,d ⎠_x000D_ | D4: 0 | E4: 0 | F4: ⎛ D ⎞⎛ A,B,C,E ⎞_x000D_ ⎝ ∅ ⎠⎝ a,b,c,d ⎠_x000D_ | G4: 0 | H4: 0 | I4: ⎛ D ⎞⎛ A,B,C,E ⎞_x000D_ ⎝ ∅ ⎠⎝ a,b,c,d ⎠_x000D_ | J4: 0 | K4: 13.26 | L4: =ABS(D4-G4)/IF(D4=0,1,D4) -> 0 | M4: =ABS(D4-J4)/IF(D4=0,1,D4) -> 0 | N4: =ROUND(IF(E4<H4, -(H4/IF(E4=0,1,E4)), IF(E4=0,1,E4)/IF(H4=0,1,H4)), 2) -> 1 | O4: =ROUND(IF(H4<K4, -(K4/IF(H4=0,1,H4)), IF(H4=0,1,H4)/IF(K4=0,1,K4)), 2) -> -13.26
A5: 3 | B5: ABCDE_{t+1}|BCDE_{t} | C5: ⎛ C ⎞⎛ A,B,D,E ⎞_x000D_ ⎝ ∅ ⎠⎝ b,c,d,e ⎠_x000D_ | D5: 0 | E5: 0 | F5: ⎛ C,D ⎞⎛ A,B,E ⎞_x000D_ ⎝ ∅ ⎠⎝ b,c,d,e ⎠_x000D_ | G5: 0 | H5: 0 | I5: ⎛ C,D ⎞⎛ A,B,E ⎞_x000D_ ⎝ ∅ ⎠⎝ b,c,d,e ⎠_x000D_ | J5: 0 | K5: 12.15 | L5: =ABS(D5-G5)/IF(D5=0,1,D5) -> 0 | M5: =ABS(D5-J5)/IF(D5=0,1,D5) -> 0 | N5: =ROUND(IF(E5<H5, -(H5/IF(E5=0,1,E5)), IF(E5=0,1,E5)/IF(H5=0,1,H5)), 2) -> 1 | O5: =ROUND(IF(H5<K5, -(K5/IF(H5=0,1,H5)), IF(H5=0,1,H5)/IF(K5=0,1,K5)), 2) -> -12.15
A6: 4 | B6: ABCDE_{t+1}|BCD_{t} | C6: ⎛ C ⎞⎛ A,B,D,E ⎞_x000D_ ⎝ ∅ ⎠⎝ b,c,d ⎠_x000D_ | D6: 0 | E6: 0.01 | F6: ⎛ C,D ⎞⎛ A,B,E ⎞_x000D_ ⎝ ∅ ⎠⎝ b,c,d ⎠_x000D_ | G6: 0 | H6: 0 | I6: ⎛ C,D ⎞⎛ A,B,E ⎞_x000D_ ⎝ ∅ ⎠⎝ b,c,d ⎠_x000D_ | J6: 0 | K6: 12.41 | L6: =ABS(D6-G6)/IF(D6=0,1,D6) -> 0 | M6: =ABS(D6-J6)/IF(D6=0,1,D6) -> 0 | N6: =ROUND(IF(E6<H6, -(H6/IF(E6=0,1,E6)), IF(E6=0,1,E6)/IF(H6=0,1,H6)), 2) -> 0.01 | O6: =ROUND(IF(H6<K6, -(K6/IF(H6=0,1,H6)), IF(H6=0,1,H6)/IF(K6=0,1,K6)), 2) -> -12.41
A7: 5 | B7: ABCDE_{t+1}|ACE_{t} | C7: ⎛ C ⎞⎛ A,B,D,E ⎞_x000D_ ⎝ ∅ ⎠⎝ a,c,e ⎠_x000D_ | D7: 0 | E7: 0.02 | F7: ⎛ ∅ ⎞⎛ A,B,C,D,E ⎞_x000D_ ⎝ a ⎠⎝ c,e ⎠_x000D_ | G7: 0 | H7: 0 | I7: ⎛ ∅ ⎞⎛ A,B,C,D,E ⎞_x000D_ ⎝ a ⎠⎝ c,e ⎠_x000D_ | J7: 0 | K7: 12.68 | L7: =ABS(D7-G7)/IF(D7=0,1,D7) -> 0 | M7: =ABS(D7-J7)/IF(D7=0,1,D7) -> 0 | N7: =ROUND(IF(E7<H7, -(H7/IF(E7=0,1,E7)), IF(E7=0,1,E7)/IF(H7=0,1,H7)), 2) -> 0.02 | O7: =ROUND(IF(H7<K7, -(K7/IF(H7=0,1,H7)), IF(H7=0,1,H7)/IF(K7=0,1,K7)), 2) -> -12.68
A8: 6 | B8: ABCDE_{t+1}|BD_{t} | C8: ⎛ B ⎞⎛ A,C,D,E ⎞_x000D_ ⎝ ∅ ⎠⎝ b,d ⎠_x000D_ | D8: 0 | E8: 0.06 | F8: ⎛ B,C,D ⎞⎛ A,E ⎞_x000D_ ⎝ ∅ ⎠⎝ b,d ⎠_x000D_ | G8: 0 | H8: 0 | I8: ⎛ B,C,D ⎞⎛ A,E ⎞_x000D_ ⎝ ∅ ⎠⎝ b,d ⎠_x000D_ | J8: 0 | K8: 13.22 | L8: =ABS(D8-G8)/IF(D8=0,1,D8) -> 0 | M8: =ABS(D8-J8)/IF(D8=0,1,D8) -> 0 | N8: =ROUND(IF(E8<H8, -(H8/IF(E8=0,1,E8)), IF(E8=0,1,E8)/IF(H8=0,1,H8)), 2) -> 0.06 | O8: =ROUND(IF(H8<K8, -(K8/IF(H8=0,1,H8)), IF(H8=0,1,H8)/IF(K8=0,1,K8)), 2) -> -13.22
A9: 7 | B9: ABCDE_{t+1}|ABDE_{t} | C9: ⎛ D ⎞⎛ A,B,C,E ⎞_x000D_ ⎝ ∅ ⎠⎝ a,b,d,e ⎠_x000D_ | D9: 0 | E9: 0.27 | F9: ⎛ D ⎞⎛ A,B,C,E ⎞_x000D_ ⎝ ∅ ⎠⎝ a,b,d,e ⎠_x000D_ | G9: 0 | H9: 0 | I9: ⎛ D ⎞⎛ A,B,C,E ⎞_x000D_ ⎝ ∅ ⎠⎝ a,b,d,e ⎠_x000D_ | J9: 0 | K9: 12.73 | L9: =ABS(D9-G9)/IF(D9=0,1,D9) -> 0 | M9: =ABS(D9-J9)/IF(D9=0,1,D9) -> 0 | N9: =ROUND(IF(E9<H9, -(H9/IF(E9=0,1,E9)), IF(E9=0,1,E9)/IF(H9=0,1,H9)), 2) -> 0.27 | O9: =ROUND(IF(H9<K9, -(K9/IF(H9=0,1,H9)), IF(H9=0,1,H9)/IF(K9=0,1,K9)), 2) -> -12.73
A10: 8 | B10: ABCD_{t+1}|ABCDE_{t} | C10: ⎛ D ⎞⎛ A,B,C ⎞_x000D_ ⎝ ∅ ⎠⎝ a,b,c,d,e ⎠_x000D_ | D10: 0 | E10: 0.01 | F10: ⎛ D ⎞⎛ A,B,C ⎞_x000D_ ⎝ ∅ ⎠⎝ a,b,c,d,e ⎠_x000D_ | G10: 0 | H10: 0 | I10: ⎛ D ⎞⎛ A,B,C ⎞_x000D_ ⎝ ∅ ⎠⎝ a,b,c,d,e ⎠_x000D_ | J10: 0 | K10: 13.64 | L10: =ABS(D10-G10)/IF(D10=0,1,D10) -> 0 | M10: =ABS(D10-J10)/IF(D10=0,1,D10) -> 0 | N10: =ROUND(IF(E10<H10, -(H10/IF(E10=0,1,E10)), IF(E10=0,1,E10)/IF(H10=0,1,H10)), 2) -> 0.01 | O10: =ROUND(IF(H10<K10, -(K10/IF(H10=0,1,H10)), IF(H10=0,1,H10)/IF(K10=0,1,K10)), 2) -> -13.64
A11: 9 | B11: ABCD_{t+1}|ABCD_{t} | C11: ⎛ D ⎞⎛ A,B,C ⎞_x000D_ ⎝ ∅ ⎠⎝ a,b,c,d ⎠_x000D_ | D11: 0 | E11: 0 | F11: ⎛ D ⎞⎛ A,B,C ⎞_x000D_ ⎝ ∅ ⎠⎝ a,b,c,d ⎠_x000D_ | G11: 0 | H11: 0 | I11: ⎛ D ⎞⎛ A,B,C ⎞_x000D_ ⎝ ∅ ⎠⎝ a,b,c,d ⎠_x000D_ | J11: 0 | K11: 12.99 | L11: =ABS(D11-G11)/IF(D11=0,1,D11) -> 0 | M11: =ABS(D11-J11)/IF(D11=0,1,D11) -> 0 | N11: =ROUND(IF(E11<H11, -(H11/IF(E11=0,1,E11)), IF(E11=0,1,E11)/IF(H11=0,1,H11)), 2) -> 1 | O11: =ROUND(IF(H11<K11, -(K11/IF(H11=0,1,H11)), IF(H11=0,1,H11)/IF(K11=0,1,K11)), 2) -> -12.99
A12: 10 | B12: ABCD_{t+1}|BCDE_{t} | C12: ⎛ C ⎞⎛ A,B,D ⎞_x000D_ ⎝ ∅ ⎠⎝ b,c,d,e ⎠_x000D_ | D12: 0 | E12: 0 | F12: ⎛ C,D ⎞⎛ A,B ⎞_x000D_ ⎝ ∅ ⎠⎝ b,c,d,e ⎠_x000D_ | G12: 0 | H12: 0 | I12: ⎛ C,D ⎞⎛ A,B ⎞_x000D_ ⎝ ∅ ⎠⎝ b,c,d,e ⎠_x000D_ | J12: 0 | K12: 12.75 | L12: =ABS(D12-G12)/IF(D12=0,1,D12) -> 0 | M12: =ABS(D12-J12)/IF(D12=0,1,D12) -> 0 | N12: =ROUND(IF(E12<H12, -(H12/IF(E12=0,1,E12)), IF(E12=0,1,E12)/IF(H12=0,1,H12)), 2) -> 1 | O12: =ROUND(IF(H12<K12, -(K12/IF(H12=0,1,H12)), IF(H12=0,1,H12)/IF(K12=0,1,K12)), 2) -> -12.75
A13: 11 | B13: ABCD_{t+1}|BCD_{t} | C13: ⎛ C ⎞⎛ A,B,D ⎞_x000D_ ⎝ ∅ ⎠⎝ b,c,d ⎠_x000D_ | D13: 0 | E13: 0.01 | F13: ⎛ C,D ⎞⎛ A,B ⎞_x000D_ ⎝ ∅ ⎠⎝ b,c,d ⎠_x000D_ | G13: 0 | H13: 0 | I13: ⎛ C,D ⎞⎛ A,B ⎞_x000D_ ⎝ ∅ ⎠⎝ b,c,d ⎠_x000D_ | J13: 0 | K13: 13.08 | L13: =ABS(D13-G13)/IF(D13=0,1,D13) -> 0 | M13: =ABS(D13-J13)/IF(D13=0,1,D13) -> 0 | N13: =ROUND(IF(E13<H13, -(H13/IF(E13=0,1,E13)), IF(E13=0,1,E13)/IF(H13=0,1,H13)), 2) -> 0.01 | O13: =ROUND(IF(H13<K13, -(K13/IF(H13=0,1,H13)), IF(H13=0,1,H13)/IF(K13=0,1,K13)), 2) -> -13.08
A14: 12 | B14: ABCD_{t+1}|ACE_{t} | C14: ⎛ C ⎞⎛ A,B,D ⎞_x000D_ ⎝ ∅ ⎠⎝ a,c,e ⎠_x000D_ | D14: 0 | E14: 0.02 | F14: ⎛ ∅ ⎞⎛ A,B,C,D ⎞_x000D_ ⎝ a ⎠⎝ c,e ⎠_x000D_ | G14: 0 | H14: 0 | I14: ⎛ ∅ ⎞⎛ A,B,C,D ⎞_x000D_ ⎝ a ⎠⎝ c,e ⎠_x000D_ | J14: 0 | K14: 12.94 | L14: =ABS(D14-G14)/IF(D14=0,1,D14) -> 0 | M14: =ABS(D14-J14)/IF(D14=0,1,D14) -> 0 | N14: =ROUND(IF(E14<H14, -(H14/IF(E14=0,1,E14)), IF(E14=0,1,E14)/IF(H14=0,1,H14)), 2) -> 0.02 | O14: =ROUND(IF(H14<K14, -(K14/IF(H14=0,1,H14)), IF(H14=0,1,H14)/IF(K14=0,1,K14)), 2) -> -12.94
... A51: 49 | B51: ABDE_{t+1}|ABDE_{t} | C51: ⎛ D ⎞⎛ A,B,E ⎞_x000D_ ⎝ ∅ ⎠⎝ a,b,d,e ⎠_x000D_ | D51: 0 | E51: 0.21 | F51: ⎛ D ⎞⎛ A,B,E ⎞_x000D_ ⎝ ∅ ⎠⎝ a,b,d,e ⎠_x000D_ | G51: 0 | H51: 0 | I51: ⎛ D ⎞⎛ A,B,E ⎞_x000D_ ⎝ ∅ ⎠⎝ a,b,d,e ⎠_x000D_ | J51: 0 | K51: 11.64 | L51: =ABS(D51-G51)/IF(D51=0,1,D51) -> 0 | M51: =ABS(D51-J51)/IF(D51=0,1,D51) -> 0 | N51: =ROUND(IF(E51<H51, -(H51/IF(E51=0,1,E51)), IF(E51=0,1,E51)/IF(H51=0,1,H51)), 2) -> 0.21 | O51: =ROUND(IF(H51<K51, -(K51/IF(H51=0,1,H51)), IF(H51=0,1,H51)/IF(K51=0,1,K51)), 2) -> -11.64
I52: PROMEDIO | L52: =AVERAGE(L$3:L$51) -> 0.017959184 | M52: =AVERAGE(M$3:M$51) -> 0.017959184 | N52: =AVERAGE(N$3:N$51) -> 0.33061224 | O52: =AVERAGE(O$3:O$51) -> -170.12878
I53: MINIMO | L53: =MIN(L$3:L$51) -> 0 | M53: =MIN(M$3:M$51) -> 0 | N53: =MIN(N$3:N$51) -> -0.01 | O53: =MIN(O$3:O$51) -> -1475
I54: MAXIMO | L54: =MAX(L$3:L$51) -> 0.5 | M54: =MAX(M$3:M$51) -> 0.5 | N54: =MAX(N$3:N$51) -> 1 | O54: =MAX(O$3:O$51) -> -9.47
L55: % Perdida Pro | M55: % Perdida MP | N55: SpeedUp Pro (X) | O55: SpeedUp MP (X)

Sheet 10 Elementos
A1: Prueba | B1: Subsistema | C1: Pyphi | F1: Proyecto (Pro) | I1: Proyecto Paralelo MP | L1: Comparacion
C2: Particion | D2: Perdida Phi | E2: Tiempo Phi | F2: Particion | G2: Perdida Pro | H2: Tiempo Pro | I2: Particion | J2: Perdida MP | K2: Tiempo MP | L2: % Perdida Pro | M2: % Perdida MP | N2: SpeedUp Pro (X) | O2: SpeedUp MP (X)
A3: 1 | B3: ABCDEFGHIJ_{t+1}|ABCDEFGHIJ_{t} | C3: ⎛ I ⎞⎛ A,B,C,D,E,F,G,H,J ⎞_x000D_ ⎝ ∅ ⎠⎝ a,b,c,d,e,f,g,h,i,j ⎠_x000D_ | D3: 0.47 | E3: 114.3 | F3: ⎛ I ⎞⎛ A,B,C,D,E,F,G,H,J ⎞_x000D_ ⎝ ∅ ⎠⎝ a,b,c,d,e,f,g,h,i,j ⎠_x000D_ | G3: 0.47 | H3: 0.11 | I3: ⎛ I ⎞⎛ A,B,C,D,E,F,G,H,J ⎞_x000D_ ⎝ ∅ ⎠⎝ a,b,c,d,e,f,g,h,i,j ⎠_x000D_ | J3: 0.47 | K3: 12.73 | L3: =ABS(D3-G3)/IF(D3=0,1,D3) -> 0 | M3: =ABS(D3-J3)/IF(D3=0,1,D3) -> 0 | N3: =ROUND(IF(E3<H3, -(H3/IF(E3=0,1,E3)), IF(E3=0,1,E3)/IF(H3=0,1,H3)), 2) -> 1039.09 | O3: =ROUND(IF(H3<K3, -(K3/IF(H3=0,1,H3)), IF(H3=0,1,H3)/IF(K3=0,1,K3)), 2) -> -115.73
A4: 2 | B4: ABCDEFGHIJ_{t+1}|ABCDEFGHI_{t} | C4: ⎛ G ⎞⎛ A,B,C,D,E,F,H,I,J ⎞_x000D_ ⎝ ∅ ⎠⎝ a,b,c,d,e,f,g,h,i ⎠_x000D_ | D4: 0 | E4: 56.06 | F4: ⎛ G ⎞⎛ A,B,C,D,E,F,H,I,J ⎞_x000D_ ⎝ ∅ ⎠⎝ a,b,c,d,e,f,g,h,i ⎠_x000D_ | G4: 0 | H4: 0.05 | I4: ⎛ G ⎞⎛ A,B,C,D,E,F,H,I,J ⎞_x000D_ ⎝ ∅ ⎠⎝ a,b,c,d,e,f,g,h,i ⎠_x000D_ | J4: 0 | K4: 12.69 | L4: =ABS(D4-G4)/IF(D4=0,1,D4) -> 0 | M4: =ABS(D4-J4)/IF(D4=0,1,D4) -> 0 | N4: =ROUND(IF(E4<H4, -(H4/IF(E4=0,1,E4)), IF(E4=0,1,E4)/IF(H4=0,1,H4)), 2) -> 1121.2 | O4: =ROUND(IF(H4<K4, -(K4/IF(H4=0,1,H4)), IF(H4=0,1,H4)/IF(K4=0,1,K4)), 2) -> -253.8
A5: 3 | B5: ABCDEFGHIJ_{t+1}|BCDEFGHIJ_{t} | C5: ⎛ G ⎞⎛ A,B,C,D,E,F,H,I,J ⎞_x000D_ ⎝ ∅ ⎠⎝ b,c,d,e,f,g,h,i,j ⎠_x000D_ | D5: 0 | E5: 56.05 | F5: ⎛ G ⎞⎛ A,B,C,D,E,F,H,I,J ⎞_x000D_ ⎝ ∅ ⎠⎝ b,c,d,e,f,g,h,i,j ⎠_x000D_ | G5: 0 | H5: 0.05 | I5: ⎛ G ⎞⎛ A,B,C,D,E,F,H,I,J ⎞_x000D_ ⎝ ∅ ⎠⎝ b,c,d,e,f,g,h,i,j ⎠_x000D_ | J5: 0 | K5: 12.72 | L5: =ABS(D5-G5)/IF(D5=0,1,D5) -> 0 | M5: =ABS(D5-J5)/IF(D5=0,1,D5) -> 0 | N5: =ROUND(IF(E5<H5, -(H5/IF(E5=0,1,E5)), IF(E5=0,1,E5)/IF(H5=0,1,H5)), 2) -> 1121 | O5: =ROUND(IF(H5<K5, -(K5/IF(H5=0,1,H5)), IF(H5=0,1,H5)/IF(K5=0,1,K5)), 2) -> -254.4
A6: 4 | B6: ABCDEFGHIJ_{t+1}|BCDEFGHI_{t} | C6: ⎛ B ⎞⎛ A,C,D,E,F,G,H,I,J ⎞_x000D_ ⎝ ∅ ⎠⎝ b,c,d,e,f,g,h,i ⎠_x000D_ | D6: 0.01 | E6: 28.71 | F6: ⎛ B ⎞⎛ A,C,D,E,F,G,H,I,J ⎞_x000D_ ⎝ ∅ ⎠⎝ b,c,d,e,f,g,h,i ⎠_x000D_ | G6: 0.01 | H6: 0.03 | I6: ⎛ B ⎞⎛ A,C,D,E,F,G,H,I,J ⎞_x000D_ ⎝ ∅ ⎠⎝ b,c,d,e,f,g,h,i ⎠_x000D_ | J6: 0.01 | K6: 12.76 | L6: =ABS(D6-G6)/IF(D6=0,1,D6) -> 0 | M6: =ABS(D6-J6)/IF(D6=0,1,D6) -> 0 | N6: =ROUND(IF(E6<H6, -(H6/IF(E6=0,1,E6)), IF(E6=0,1,E6)/IF(H6=0,1,H6)), 2) -> 957 | O6: =ROUND(IF(H6<K6, -(K6/IF(H6=0,1,H6)), IF(H6=0,1,H6)/IF(K6=0,1,K6)), 2) -> -425.33
A7: 5 | B7: ABCDEFGHIJ_{t+1}|ACEGI_{t} | C7: ⎛ E ⎞⎛ A,B,C,D,F,G,H,I,J ⎞_x000D_ ⎝ ∅ ⎠⎝ a,c,e,g,i ⎠_x000D_ | D7: 0.02 | E7: 3.46 | F7: ⎛ E ⎞⎛ A,B,C,D,F,G,H,I,J ⎞_x000D_ ⎝ ∅ ⎠⎝ a,c,e,g,i ⎠_x000D_ | G7: 0.02 | H7: 0.01 | I7: ⎛ E ⎞⎛ A,B,C,D,F,G,H,I,J ⎞_x000D_ ⎝ ∅ ⎠⎝ a,c,e,g,i ⎠_x000D_ | J7: 0.02 | K7: 12.61 | L7: =ABS(D7-G7)/IF(D7=0,1,D7) -> 0 | M7: =ABS(D7-J7)/IF(D7=0,1,D7) -> 0 | N7: =ROUND(IF(E7<H7, -(H7/IF(E7=0,1,E7)), IF(E7=0,1,E7)/IF(H7=0,1,H7)), 2) -> 346 | O7: =ROUND(IF(H7<K7, -(K7/IF(H7=0,1,H7)), IF(H7=0,1,H7)/IF(K7=0,1,K7)), 2) -> -1261
A8: 6 | B8: ABCDEFGHIJ_{t+1}|BDFHJ_{t} | C8: ⎛ I ⎞⎛ A,B,C,D,E,F,G,H,J ⎞_x000D_ ⎝ ∅ ⎠⎝ b,d,f,h,j ⎠_x000D_ | D8: 0 | E8: 3.42 | F8: ⎛ I ⎞⎛ A,B,C,D,E,F,G,H,J ⎞_x000D_ ⎝ ∅ ⎠⎝ b,d,f,h,j ⎠_x000D_ | G8: 0 | H8: 0 | I8: ⎛ I ⎞⎛ A,B,C,D,E,F,G,H,J ⎞_x000D_ ⎝ ∅ ⎠⎝ b,d,f,h,j ⎠_x000D_ | J8: 0 | K8: 13.59 | L8: =ABS(D8-G8)/IF(D8=0,1,D8) -> 0 | M8: =ABS(D8-J8)/IF(D8=0,1,D8) -> 0 | N8: =ROUND(IF(E8<H8, -(H8/IF(E8=0,1,E8)), IF(E8=0,1,E8)/IF(H8=0,1,H8)), 2) -> 3.42 | O8: =ROUND(IF(H8<K8, -(K8/IF(H8=0,1,H8)), IF(H8=0,1,H8)/IF(K8=0,1,K8)), 2) -> -13.59
A9: 7 | B9: ABCDEFGHIJ_{t+1}|ABDEGHJ_{t} | C9: ⎛ J ⎞⎛ A,B,C,D,E,F,G,H,I ⎞_x000D_ ⎝ ∅ ⎠⎝ a,b,d,e,g,h,j ⎠_x000D_ | D9: 0.01 | E9: 14.08 | F9: ⎛ J ⎞⎛ A,B,C,D,E,F,G,H,I ⎞_x000D_ ⎝ ∅ ⎠⎝ a,b,d,e,g,h,j ⎠_x000D_ | G9: 0.01 | H9: 0.01 | I9: ⎛ J ⎞⎛ A,B,C,D,E,F,G,H,I ⎞_x000D_ ⎝ ∅ ⎠⎝ a,b,d,e,g,h,j ⎠_x000D_ | J9: 0.01 | K9: 13.28 | L9: =ABS(D9-G9)/IF(D9=0,1,D9) -> 0 | M9: =ABS(D9-J9)/IF(D9=0,1,D9) -> 0 | N9: =ROUND(IF(E9<H9, -(H9/IF(E9=0,1,E9)), IF(E9=0,1,E9)/IF(H9=0,1,H9)), 2) -> 1408 | O9: =ROUND(IF(H9<K9, -(K9/IF(H9=0,1,H9)), IF(H9=0,1,H9)/IF(K9=0,1,K9)), 2) -> -1328
A10: 8 | B10: ABCDEFGHI_{t+1}|ABCDEFGHIJ_{t} | C10: ⎛ I ⎞⎛ A,B,C,D,E,F,G,H ⎞_x000D_ ⎝ ∅ ⎠⎝ a,b,c,d,e,f,g,h,i,j ⎠_x000D_ | D10: 0.47 | E10: 51.43 | F10: ⎛ I ⎞⎛ A,B,C,D,E,F,G,H ⎞_x000D_ ⎝ ∅ ⎠⎝ a,b,c,d,e,f,g,h,i,j ⎠_x000D_ | G10: 0.47 | H10: 0.1 | I10: ⎛ I ⎞⎛ A,B,C,D,E,F,G,H ⎞_x000D_ ⎝ ∅ ⎠⎝ a,b,c,d,e,f,g,h,i,j ⎠_x000D_ | J10: 0.47 | K10: 12.31 | L10: =ABS(D10-G10)/IF(D10=0,1,D10) -> 0 | M10: =ABS(D10-J10)/IF(D10=0,1,D10) -> 0 | N10: =ROUND(IF(E10<H10, -(H10/IF(E10=0,1,E10)), IF(E10=0,1,E10)/IF(H10=0,1,H10)), 2) -> 514.3 | O10: =ROUND(IF(H10<K10, -(K10/IF(H10=0,1,H10)), IF(H10=0,1,H10)/IF(K10=0,1,K10)), 2) -> -123.1
A11: 9 | B11: ABCDEFGHI_{t+1}|ABCDEFGHI_{t} | C11: ⎛ G ⎞⎛ A,B,C,D,E,F,H,I ⎞_x000D_ ⎝ ∅ ⎠⎝ a,b,c,d,e,f,g,h,i ⎠_x000D_ | D11: 0 | E11: 25.83 | F11: ⎛ G ⎞⎛ A,B,C,D,E,F,H,I ⎞_x000D_ ⎝ ∅ ⎠⎝ a,b,c,d,e,f,g,h,i ⎠_x000D_ | G11: 0 | H11: 0.05 | I11: ⎛ G ⎞⎛ A,B,C,D,E,F,H,I ⎞_x000D_ ⎝ ∅ ⎠⎝ a,b,c,d,e,f,g,h,i ⎠_x000D_ | J11: 0 | K11: 12.47 | L11: =ABS(D11-G11)/IF(D11=0,1,D11) -> 0 | M11: =ABS(D11-J11)/IF(D11=0,1,D11) -> 0 | N11: =ROUND(IF(E11<H11, -(H11/IF(E11=0,1,E11)), IF(E11=0,1,E11)/IF(H11=0,1,H11)), 2) -> 516.6 | O11: =ROUND(IF(H11<K11, -(K11/IF(H11=0,1,H11)), IF(H11=0,1,H11)/IF(K11=0,1,K11)), 2) -> -249.4
A12: 10 | B12: ABCDEFGHI_{t+1}|BCDEFGHIJ_{t} | C12: ⎛ G ⎞⎛ A,B,C,D,E,F,H,I ⎞_x000D_ ⎝ ∅ ⎠⎝ b,c,d,e,f,g,h,i,j ⎠_x000D_ | D12: 0 | E12: 25.55 | F12: ⎛ G ⎞⎛ A,B,C,D,E,F,H,I ⎞_x000D_ ⎝ ∅ ⎠⎝ b,c,d,e,f,g,h,i,j ⎠_x000D_ | G12: 0 | H12: 0.11 | I12: ⎛ G ⎞⎛ A,B,C,D,E,F,H,I ⎞_x000D_ ⎝ ∅ ⎠⎝ b,c,d,e,f,g,h,i,j ⎠_x000D_ | J12: 0 | K12: 12.64 | L12: =ABS(D12-G12)/IF(D12=0,1,D12) -> 0 | M12: =ABS(D12-J12)/IF(D12=0,1,D12) -> 0 | N12: =ROUND(IF(E12<H12, -(H12/IF(E12=0,1,E12)), IF(E12=0,1,E12)/IF(H12=0,1,H12)), 2) -> 232.27 | O12: =ROUND(IF(H12<K12, -(K12/IF(H12=0,1,H12)), IF(H12=0,1,H12)/IF(K12=0,1,K12)), 2) -> -114.91
A13: 11 | B13: ABCDEFGHI_{t+1}|BCDEFGHI_{t} | C13: ⎛ B ⎞⎛ A,C,D,E,F,G,H,I ⎞_x000D_ ⎝ ∅ ⎠⎝ b,c,d,e,f,g,h,i ⎠_x000D_ | D13: 0.01 | E13: 13.29 | F13: ⎛ B ⎞⎛ A,C,D,E,F,G,H,I ⎞_x000D_ ⎝ ∅ ⎠⎝ b,c,d,e,f,g,h,i ⎠_x000D_ | G13: 0.01 | H13: 0.03 | I13: ⎛ B ⎞⎛ A,C,D,E,F,G,H,I ⎞_x000D_ ⎝ ∅ ⎠⎝ b,c,d,e,f,g,h,i ⎠_x000D_ | J13: 0.01 | K13: 14.12 | L13: =ABS(D13-G13)/IF(D13=0,1,D13) -> 0 | M13: =ABS(D13-J13)/IF(D13=0,1,D13) -> 0 | N13: =ROUND(IF(E13<H13, -(H13/IF(E13=0,1,E13)), IF(E13=0,1,E13)/IF(H13=0,1,H13)), 2) -> 443 | O13: =ROUND(IF(H13<K13, -(K13/IF(H13=0,1,H13)), IF(H13=0,1,H13)/IF(K13=0,1,K13)), 2) -> -470.67
A14: 12 | B14: ABCDEFGHI_{t+1}|ACEGI_{t} | C14: ⎛ E ⎞⎛ A,B,C,D,F,G,H,I ⎞_x000D_ ⎝ ∅ ⎠⎝ a,c,e,g,i ⎠_x000D_ | D14: 0.02 | E14: 1.63 | F14: ⎛ E ⎞⎛ A,B,C,D,F,G,H,I ⎞_x000D_ ⎝ ∅ ⎠⎝ a,c,e,g,i ⎠_x000D_ | G14: 0.02 | H14: 0.01 | I14: ⎛ E ⎞⎛ A,B,C,D,F,G,H,I ⎞_x000D_ ⎝ ∅ ⎠⎝ a,c,e,g,i ⎠_x000D_ | J14: 0.02 | K14: 13.71 | L14: =ABS(D14-G14)/IF(D14=0,1,D14) -> 0 | M14: =ABS(D14-J14)/IF(D14=0,1,D14) -> 0 | N14: =ROUND(IF(E14<H14, -(H14/IF(E14=0,1,E14)), IF(E14=0,1,E14)/IF(H14=0,1,H14)), 2) -> 163 | O14: =ROUND(IF(H14<K14, -(K14/IF(H14=0,1,H14)), IF(H14=0,1,H14)/IF(K14=0,1,K14)), 2) -> -1371
... A51: 49 | B51: ABDEGHJ_{t+1}|ABDEGHJ_{t} | C51: ⎛ J ⎞⎛ A,B,D,E,G,H ⎞_x000D_ ⎝ ∅ ⎠⎝ a,b,d,e,g,h,j ⎠_x000D_ | D51: 0.01 | E51: 1.72 | F51: ⎛ J ⎞⎛ A,B,D,E,G,H ⎞_x000D_ ⎝ ∅ ⎠⎝ a,b,d,e,g,h,j ⎠_x000D_ | G51: 0.01 | H51: 0.01 | I51: ⎛ J ⎞⎛ A,B,D,E,G,H ⎞_x000D_ ⎝ ∅ ⎠⎝ a,b,d,e,g,h,j ⎠_x000D_ | J51: 0.01 | K51: 12.26 | L51: =ABS(D51-G51)/IF(D51=0,1,D51) -> 0 | M51: =ABS(D51-J51)/IF(D51=0,1,D51) -> 0 | N51: =ROUND(IF(E51<H51, -(H51/IF(E51=0,1,E51)), IF(E51=0,1,E51)/IF(H51=0,1,H51)), 2) -> 172 | O51: =ROUND(IF(H51<K51, -(K51/IF(H51=0,1,H51)), IF(H51=0,1,H51)/IF(K51=0,1,K51)), 2) -> -1226
I52: PROMEDIO | L52: =AVERAGE(L$3:L$51) -> 0.00042517007 | M52: =AVERAGE(M$3:M$51) -> 0.00042517007 | N52: =AVERAGE(N$3:N$51) -> 298.78694 | O52: =AVERAGE(O$3:O$51) -> -495.69776
I53: MINIMO | L53: =MIN(L$3:L$51) -> 0 | M53: =MIN(M$3:M$51) -> 0 | N53: =MIN(N$3:N$51) -> 0.12 | O53: =MIN(O$3:O$51) -> -1371
I54: MAXIMO | L54: =MAX(L$3:L$51) -> 0.020833333 | M54: =MAX(M$3:M$51) -> 0.020833333 | N54: =MAX(N$3:N$51) -> 1408 | O54: =MAX(O$3:O$51) -> -12.3
L55: % Perdida Pro | M55: % Perdida MP | N55: SpeedUp Pro (X) | O55: SpeedUp MP (X)

Sheet 15 Elementos
A1: Prueba | B1: Subsistema | C1: Pyphi | F1: Proyecto (Pro) | I1: Proyecto Paralelo MP | L1: Proyecto Paralelo CUDA | O1: Comparacion
C2: Particion | D2: Perdida Phi | E2: Tiempo Phi | F2: Particion | G2: Perdida Pro | H2: Tiempo Pro | I2: Particion | J2: Perdida MP | K2: Tiempo MP | L2: Particion | M2: Perdida CUDA | N2: Tiempo CUDA | O2: % Perdida Pro | P2: % Perdida MP | Q2: % Perdida CUDA | R2: SpeedUp Pro (X) | S2: SpeedUp MP (X) | T2: SpeedUp CUDA (X)
A3: 1 | B3: ABCDEFGHIJKLMNO_{t+1}|ABCDEFGHIJKLMNO_{t} | C3: ⎛ ∅ ⎞⎛ A,B,C,D,E,F,G,H,I,J,K,L,M,N,O ⎞ ⎝ a ⎠⎝ b,c,d,e,f,g,h,i,j,k,l,m,n,o ⎠ | D3: 0 | E3: 38.96 | F3: ⎛ ∅ ⎞⎛ A,B,C,D,E,F,G,H,I,J,K,L,M,N,O ⎞_x000D_ ⎝ a ⎠⎝ b,c,d,e,f,g,h,i,j,k,l,m,n,o ⎠_x000D_ | G3: 0 | H3: 8.27 | I3: ⎛ ∅ ⎞⎛ A,B,C,D,E,F,G,H,I,J,K,L,M,N,O ⎞_x000D_ ⎝ a ⎠⎝ b,c,d,e,f,g,h,i,j,k,l,m,n,o ⎠_x000D_ | J3: 0 | K3: 15.53 | L3: ⎛ ∅ ⎞⎛ A,B,C,D,E,F,G,H,I,J,K,L,M,N,O ⎞_x000D_ ⎝ a ⎠⎝ b,c,d,e,f,g,h,i,j,k,l,m,n,o ⎠_x000D_ | M3: 0 | N3: 7.5 | O3: =ABS(D3-G3)/IF(D3=0,1,D3) -> 0 | P3: =ABS(D3-J3)/IF(D3=0,1,D3) -> 0 | Q3: =ABS(D3-M3)/IF(D3=0,1,D3) -> 0 | R3: =ROUND(IF(E3<H3, -(H3/IF(E3=0,1,E3)), IF(E3=0,1,E3)/IF(H3=0,1,H3)), 2) -> 4.71 | S3: =ROUND(IF(H3<K3, -(K3/IF(H3=0,1,H3)), IF(H3=0,1,H3)/IF(K3=0,1,K3)), 2) -> -1.88 | T3: =ROUND(IF(H3<N3, -(N3/IF(H3=0,1,H3)), IF(H3=0,1,H3)/IF(N3=0,1,N3)), 2) -> 1.1
A4: 2 | B4: ABCDEFGHIJKLMNO_{t+1}|ABCDEFGHIJKLMN_{t} | C4: ⎛ ∅ ⎞⎛ A,B,C,D,E,F,G,H,I,J,K,L,M,N,O ⎞ ⎝ a ⎠⎝ b,c,d,e,f,g,h,i,j,k,l,m,n ⎠ | D4: 0 | E4: 40.94 | F4: ⎛ H ⎞⎛ A,B,C,D,E,F,G,I,J,K,L,M,N,O ⎞_x000D_ ⎝ ∅ ⎠⎝ a,b,c,d,e,f,g,h,i,j,k,l,m,n ⎠_x000D_ | G4: 0.03 | H4: 3.57 | I4: ⎛ H ⎞⎛ A,B,C,D,E,F,G,I,J,K,L,M,N,O ⎞_x000D_ ⎝ ∅ ⎠⎝ a,b,c,d,e,f,g,h,i,j,k,l,m,n ⎠_x000D_ | J4: 0.03 | K4: 13.32 | L4: ⎛ H ⎞⎛ A,B,C,D,E,F,G,I,J,K,L,M,N,O ⎞_x000D_ ⎝ ∅ ⎠⎝ a,b,c,d,e,f,g,h,i,j,k,l,m,n ⎠_x000D_ | M4: 0.03 | N4: 5.08 | O4: =ABS(D4-G4)/IF(D4=0,1,D4) -> 0.03 | P4: =ABS(D4-J4)/IF(D4=0,1,D4) -> 0.03 | Q4: =ABS(D4-M4)/IF(D4=0,1,D4) -> 0.03 | R4: =ROUND(IF(E4<H4, -(H4/IF(E4=0,1,E4)), IF(E4=0,1,E4)/IF(H4=0,1,H4)), 2) -> 11.47 | S4: =ROUND(IF(H4<K4, -(K4/IF(H4=0,1,H4)), IF(H4=0,1,H4)/IF(K4=0,1,K4)), 2) -> -3.73 | T4: =ROUND(IF(H4<N4, -(N4/IF(H4=0,1,H4)), IF(H4=0,1,H4)/IF(N4=0,1,N4)), 2) -> -1.42
A5: 3 | B5: ABCDEFGHIJKLMNO_{t+1}|BCDEFGHIJKLMNO_{t} | C5: ⎛ ∅ ⎞⎛ A,B,C,D,E,F,G,H,I,J,K,L,M,N,O ⎞ ⎝ b ⎠⎝ c,d,e,f,g,h,i,j,k,l,m,n,o ⎠ | D5: 0 | E5: 41.7 | F5: ⎛ ∅ ⎞⎛ A,B,C,D,E,F,G,H,I,J,K,L,M,N,O ⎞_x000D_ ⎝ o ⎠⎝ b,c,d,e,f,g,h,i,j,k,l,m,n ⎠_x000D_ | G5: 0 | H5: 5 | I5: ⎛ ∅ ⎞⎛ A,B,C,D,E,F,G,H,I,J,K,L,M,N,O ⎞_x000D_ ⎝ o ⎠⎝ b,c,d,e,f,g,h,i,j,k,l,m,n ⎠_x000D_ | J5: 0 | K5: 14.55 | L5: ⎛ ∅ ⎞⎛ A,B,C,D,E,F,G,H,I,J,K,L,M,N,O ⎞_x000D_ ⎝ o ⎠⎝ b,c,d,e,f,g,h,i,j,k,l,m,n ⎠_x000D_ | M5: 0 | N5: 6.85 | O5: =ABS(D5-G5)/IF(D5=0,1,D5) -> 0 | P5: =ABS(D5-J5)/IF(D5=0,1,D5) -> 0 | Q5: =ABS(D5-M5)/IF(D5=0,1,D5) -> 0 | R5: =ROUND(IF(E5<H5, -(H5/IF(E5=0,1,E5)), IF(E5=0,1,E5)/IF(H5=0,1,H5)), 2) -> 8.34 | S5: =ROUND(IF(H5<K5, -(K5/IF(H5=0,1,H5)), IF(H5=0,1,H5)/IF(K5=0,1,K5)), 2) -> -2.91 | T5: =ROUND(IF(H5<N5, -(N5/IF(H5=0,1,H5)), IF(H5=0,1,H5)/IF(N5=0,1,N5)), 2) -> -1.37
A6: 4 | B6: ABCDEFGHIJKLMNO_{t+1}|BCDEFGHIJKLMN_{t} | C6: ⎛ ∅ ⎞⎛ A,B,C,D,E,F,G,H,I,J,K,L,M,N,O ⎞ ⎝ b ⎠⎝ c,d,e,f,g,h,i,j,k,l,m,n ⎠ | D6: 0 | E6: 42.84 | F6: ⎛ H ⎞⎛ A,B,C,D,E,F,G,I,J,K,L,M,N,O ⎞_x000D_ ⎝ ∅ ⎠⎝ b,c,d,e,f,g,h,i,j,k,l,m,n ⎠_x000D_ | G6: 0.03 | H6: 1.84 | I6: ⎛ H ⎞⎛ A,B,C,D,E,F,G,I,J,K,L,M,N,O ⎞_x000D_ ⎝ ∅ ⎠⎝ b,c,d,e,f,g,h,i,j,k,l,m,n ⎠_x000D_ | J6: 0.03 | K6: 12.79 | L6: ⎛ H ⎞⎛ A,B,C,D,E,F,G,I,J,K,L,M,N,O ⎞_x000D_ ⎝ ∅ ⎠⎝ b,c,d,e,f,g,h,i,j,k,l,m,n ⎠_x000D_ | M6: 0.03 | N6: 4.63 | O6: =ABS(D6-G6)/IF(D6=0,1,D6) -> 0.03 | P6: =ABS(D6-J6)/IF(D6=0,1,D6) -> 0.03 | Q6: =ABS(D6-M6)/IF(D6=0,1,D6) -> 0.03 | R6: =ROUND(IF(E6<H6, -(H6/IF(E6=0,1,E6)), IF(E6=0,1,E6)/IF(H6=0,1,H6)), 2) -> 23.28 | S6: =ROUND(IF(H6<K6, -(K6/IF(H6=0,1,H6)), IF(H6=0,1,H6)/IF(K6=0,1,K6)), 2) -> -6.95 | T6: =ROUND(IF(H6<N6, -(N6/IF(H6=0,1,H6)), IF(H6=0,1,H6)/IF(N6=0,1,N6)), 2) -> -2.52
A7: 5 | B7: ABCDEFGHIJKLMNO_{t+1}|ACEGIKMO_{t} | C7: KILLED | F7: ⎛ L ⎞⎛ A,B,C,D,E,F,G,H,I,J,K,M,N,O ⎞_x000D_ ⎝ ∅ ⎠⎝ a,c,e,g,i,k,m,o ⎠_x000D_ | G7: 0 | H7: 0.04 | I7: ⎛ L ⎞⎛ A,B,C,D,E,F,G,H,I,J,K,M,N,O ⎞_x000D_ ⎝ ∅ ⎠⎝ a,c,e,g,i,k,m,o ⎠_x000D_ | J7: 0 | K7: 12.15 | L7: ⎛ L ⎞⎛ A,B,C,D,E,F,G,H,I,J,K,M,N,O ⎞_x000D_ ⎝ ∅ ⎠⎝ a,c,e,g,i,k,m,o ⎠_x000D_ | M7: 0 | N7: 4.41 | O7: =ABS(D7-G7)/IF(D7=0,1,D7) -> 0 | P7: =ABS(D7-J7)/IF(D7=0,1,D7) -> 0 | Q7: =ABS(D7-M7)/IF(D7=0,1,D7) -> 0 | R7: =ROUND(IF(E7<H7, -(H7/IF(E7=0,1,E7)), IF(E7=0,1,E7)/IF(H7=0,1,H7)), 2) -> -0.04 | S7: =ROUND(IF(H7<K7, -(K7/IF(H7=0,1,H7)), IF(H7=0,1,H7)/IF(K7=0,1,K7)), 2) -> -303.75 | T7: =ROUND(IF(H7<N7, -(N7/IF(H7=0,1,H7)), IF(H7=0,1,H7)/IF(N7=0,1,N7)), 2) -> -110.25
A8: 6 | B8: ABCDEFGHIJKLMNO_{t+1}|BDFHJLN_{t} | C8: KILLED | F8: ⎛ G ⎞⎛ A,B,C,D,E,F,H,I,J,K,L,M,N,O ⎞_x000D_ ⎝ ∅ ⎠⎝ b,d,f,h,j,l,n ⎠_x000D_ | G8: 0.01 | H8: 0.03 | I8: ⎛ G ⎞⎛ A,B,C,D,E,F,H,I,J,K,L,M,N,O ⎞_x000D_ ⎝ ∅ ⎠⎝ b,d,f,h,j,l,n ⎠_x000D_ | J8: 0.01 | K8: 12.69 | L8: ⎛ G ⎞⎛ A,B,C,D,E,F,H,I,J,K,L,M,N,O ⎞_x000D_ ⎝ ∅ ⎠⎝ b,d,f,h,j,l,n ⎠_x000D_ | M8: 0.01 | N8: 4.61 | O8: =ABS(D8-G8)/IF(D8=0,1,D8) -> 0.01 | P8: =ABS(D8-J8)/IF(D8=0,1,D8) -> 0.01 | Q8: =ABS(D8-M8)/IF(D8=0,1,D8) -> 0.01 | R8: =ROUND(IF(E8<H8, -(H8/IF(E8=0,1,E8)), IF(E8=0,1,E8)/IF(H8=0,1,H8)), 2) -> -0.03 | S8: =ROUND(IF(H8<K8, -(K8/IF(H8=0,1,H8)), IF(H8=0,1,H8)/IF(K8=0,1,K8)), 2) -> -423 | T8: =ROUND(IF(H8<N8, -(N8/IF(H8=0,1,H8)), IF(H8=0,1,H8)/IF(N8=0,1,N8)), 2) -> -153.67
A9: 7 | B9: ABCDEFGHIJKLMNO_{t+1}|ABDEGHIJKLNO_{t} | C9: KILLED | F9: ⎛ O ⎞⎛ A,B,C,D,E,F,G,H,I,J,K,L,M,N ⎞_x000D_ ⎝ ∅ ⎠⎝ a,b,d,e,g,h,j,k,m,n ⎠_x000D_ | G9: 0 | H9: 0.19 | I9: ⎛ O ⎞⎛ A,B,C,D,E,F,G,H,I,J,K,L,M,N ⎞_x000D_ ⎝ ∅ ⎠⎝ a,b,d,e,g,h,j,k,m,n ⎠_x000D_ | J9: 0 | K9: 12.46 | L9: ⎛ O ⎞⎛ A,B,C,D,E,F,G,H,I,J,K,L,M,N ⎞_x000D_ ⎝ ∅ ⎠⎝ a,b,d,e,g,h,j,k,m,n ⎠_x000D_ | M9: 0 | N9: 4.66 | O9: =ABS(D9-G9)/IF(D9=0,1,D9) -> 0 | P9: =ABS(D9-J9)/IF(D9=0,1,D9) -> 0 | Q9: =ABS(D9-M9)/IF(D9=0,1,D9) -> 0 | R9: =ROUND(IF(E9<H9, -(H9/IF(E9=0,1,E9)), IF(E9=0,1,E9)/IF(H9=0,1,H9)), 2) -> -0.19 | S9: =ROUND(IF(H9<K9, -(K9/IF(H9=0,1,H9)), IF(H9=0,1,H9)/IF(K9=0,1,K9)), 2) -> -65.58 | T9: =ROUND(IF(H9<N9, -(N9/IF(H9=0,1,H9)), IF(H9=0,1,H9)/IF(N9=0,1,N9)), 2) -> -24.53
A10: 8 | B10: ABCDEFGHIJKLMN_{t+1}|ABCDEFGHIJKLMNO_{t} | C10: ⎛ ∅ ⎞⎛ A,B,C,D,E,F,G,H,I,J,K,L,M,N ⎞ ⎝ a ⎠⎝ b,c,d,e,f,g,h,i,j,k,l,m,n,o ⎠ | D10: 0 | E10: 11.85 | F10: ⎛ ∅ ⎞⎛ A,B,C,D,E,F,G,H,I,J,K,L,M,N ⎞_x000D_ ⎝ a ⎠⎝ b,c,d,e,f,g,h,i,j,k,l,m,n,o ⎠_x000D_ | G10: 0 | H10: 7.59 | I10: ⎛ ∅ ⎞⎛ A,B,C,D,E,F,G,H,I,J,K,L,M,N ⎞_x000D_ ⎝ a ⎠⎝ b,c,d,e,f,g,h,i,j,k,l,m,n,o ⎠_x000D_ | J10: 0 | K10: 16.51 | L10: ⎛ ∅ ⎞⎛ A,B,C,D,E,F,G,H,I,J,K,L,M,N ⎞_x000D_ ⎝ a ⎠⎝ b,c,d,e,f,g,h,i,j,k,l,m,n,o ⎠_x000D_ | M10: 0 | N10: 6.64 | O10: =ABS(D10-G10)/IF(D10=0,1,D10) -> 0 | P10: =ABS(D10-J10)/IF(D10=0,1,D10) -> 0 | Q10: =ABS(D10-M10)/IF(D10=0,1,D10) -> 0 | R10: =ROUND(IF(E10<H10, -(H10/IF(E10=0,1,E10)), IF(E10=0,1,E10)/IF(H10=0,1,H10)), 2) -> 1.56 | S10: =ROUND(IF(H10<K10, -(K10/IF(H10=0,1,H10)), IF(H10=0,1,H10)/IF(K10=0,1,K10)), 2) -> -2.18 | T10: =ROUND(IF(H10<N10, -(N10/IF(H10=0,1,H10)), IF(H10=0,1,H10)/IF(N10=0,1,N10)), 2) -> 1.14
A11: 9 | B11: ABCDEFGHIJKLMN_{t+1}|ABCDEFGHIJKLMN_{t} | C11: ⎛ ∅ ⎞⎛ A,B,C,D,E,F,G,H,I,J,K,L,M,N ⎞ ⎝ a ⎠⎝ b,c,d,e,f,g,h,i,j,k,l,m,n ⎠ | D11: 0 | E11: 12.2 | F11: ⎛ H ⎞⎛ A,B,C,D,E,F,G,I,J,K,L,M,N ⎞_x000D_ ⎝ ∅ ⎠⎝ a,b,c,d,e,f,g,h,i,j,k,l,m,n ⎠_x000D_ | G11: 0.03 | H11: 3.17 | I11: ⎛ H ⎞⎛ A,B,C,D,E,F,G,I,J,K,L,M,N ⎞_x000D_ ⎝ ∅ ⎠⎝ a,b,c,d,e,f,g,h,i,j,k,l,m,n ⎠_x000D_ | J11: 0.03 | K11: 13.2 | L11: ⎛ H ⎞⎛ A,B,C,D,E,F,G,I,J,K,L,M,N ⎞_x000D_ ⎝ ∅ ⎠⎝ a,b,c,d,e,f,g,h,i,j,k,l,m,n ⎠_x000D_ | M11: 0.03 | N11: 4.82 | O11: =ABS(D11-G11)/IF(D11=0,1,D11) -> 0.03 | P11: =ABS(D11-J11)/IF(D11=0,1,D11) -> 0.03 | Q11: =ABS(D11-M11)/IF(D11=0,1,D11) -> 0.03 | R11: =ROUND(IF(E11<H11, -(H11/IF(E11=0,1,E11)), IF(E11=0,1,E11)/IF(H11=0,1,H11)), 2) -> 3.85 | S11: =ROUND(IF(H11<K11, -(K11/IF(H11=0,1,H11)), IF(H11=0,1,H11)/IF(K11=0,1,K11)), 2) -> -4.16 | T11: =ROUND(IF(H11<N11, -(N11/IF(H11=0,1,H11)), IF(H11=0,1,H11)/IF(N11=0,1,N11)), 2) -> -1.52
A12: 10 | B12: ABCDEFGHIJKLMN_{t+1}|BCDEFGHIJKLMNO_{t} | C12: ⎛ ∅ ⎞⎛ A,B,C,D,E,F,G,H,I,J,K,L,M,N ⎞ ⎝ b ⎠⎝ c,d,e,f,g,h,i,j,k,l,m,n,o ⎠ | D12: 0 | E12: 12.44 | F12: ⎛ ∅ ⎞⎛ A,B,C,D,E,F,G,H,I,J,K,L,M,N ⎞_x000D_ ⎝ o ⎠⎝ b,c,d,e,f,g,h,i,j,k,l,m,n ⎠_x000D_ | G12: 0 | H12: 4.4 | I12: ⎛ ∅ ⎞⎛ A,B,C,D,E,F,G,H,I,J,K,L,M,N ⎞_x000D_ ⎝ o ⎠⎝ b,c,d,e,f,g,h,i,j,k,l,m,n ⎠_x000D_ | J12: 0 | K12: 14.34 | L12: ⎛ ∅ ⎞⎛ A,B,C,D,E,F,G,H,I,J,K,L,M,N ⎞_x000D_ ⎝ o ⎠⎝ b,c,d,e,f,g,h,i,j,k,l,m,n ⎠_x000D_ | M12: 0 | N12: 6.68 | O12: =ABS(D12-G12)/IF(D12=0,1,D12) -> 0 | P12: =ABS(D12-J12)/IF(D12=0,1,D12) -> 0 | Q12: =ABS(D12-M12)/IF(D12=0,1,D12) -> 0 | R12: =ROUND(IF(E12<H12, -(H12/IF(E12=0,1,E12)), IF(E12=0,1,E12)/IF(H12=0,1,H12)), 2) -> 2.83 | S12: =ROUND(IF(H12<K12, -(K12/IF(H12=0,1,H12)), IF(H12=0,1,H12)/IF(K12=0,1,K12)), 2) -> -3.26 | T12: =ROUND(IF(H12<N12, -(N12/IF(H12=0,1,H12)), IF(H12=0,1,H12)/IF(N12=0,1,N12)), 2) -> -1.52
A13: 11 | B13: ABCDEFGHIJKLMN_{t+1}|BCDEFGHIJKLMN_{t} | C13: ⎛ ∅ ⎞⎛ A,B,C,D,E,F,G,H,I,J,K,L,M,N ⎞ ⎝ b ⎠⎝ c,d,e,f,g,h,i,j,k,l,m,n ⎠ | D13: 0 | E13: 11.97 | F13: ⎛ H ⎞⎛ A,B,C,D,E,F,G,I,J,K,L,M,N ⎞_x000D_ ⎝ ∅ ⎠⎝ b,c,d,e,f,g,h,i,j,k,l,m,n ⎠_x000D_ | G13: 0.03 | H13: 1.39 | I13: ⎛ H ⎞⎛ A,B,C,D,E,F,G,I,J,K,L,M,N ⎞_x000D_ ⎝ ∅ ⎠⎝ b,c,d,e,f,g,h,i,j,k,l,m,n ⎠_x000D_ | J13: 0.03 | K13: 12.98 | L13: ⎛ H ⎞⎛ A,B,C,D,E,F,G,I,J,K,L,M,N ⎞_x000D_ ⎝ ∅ ⎠⎝ b,c,d,e,f,g,h,i,j,k,l,m,n ⎠_x000D_ | M13: 0.03 | N13: 4.6 | O13: =ABS(D13-G13)/IF(D13=0,1,D13) -> 0.03 | P13: =ABS(D13-J13)/IF(D13=0,1,D13) -> 0.03 | Q13: =ABS(D13-M13)/IF(D13=0,1,D13) -> 0.03 | R13: =ROUND(IF(E13<H13, -(H13/IF(E13=0,1,E13)), IF(E13=0,1,E13)/IF(H13=0,1,H13)), 2) -> 8.61 | S13: =ROUND(IF(H13<K13, -(K13/IF(H13=0,1,H13)), IF(H13=0,1,H13)/IF(K13=0,1,K13)), 2) -> -9.34 | T13: =ROUND(IF(H13<N13, -(N13/IF(H13=0,1,H13)), IF(H13=0,1,H13)/IF(N13=0,1,N13)), 2) -> -3.31
A14: 12 | B14: ABCDEFGHIJKLMN_{t+1}|ACEGIKMO_{t} | C14: KILLED | F14: ⎛ L ⎞⎛ A,B,C,D,E,F,G,H,I,J,K,M,N ⎞_x000D_ ⎝ ∅ ⎠⎝ a,c,e,g,i,k,m,o ⎠_x000D_ | G14: 0 | H14: 0.03 | I14: ⎛ L ⎞⎛ A,B,C,D,E,F,G,H,I,J,K,M,N ⎞_x000D_ ⎝ ∅ ⎠⎝ a,c,e,g,i,k,m,o ⎠_x000D_ | J14: 0 | K14: 13.74 | L14: ⎛ L ⎞⎛ A,B,C,D,E,F,G,H,I,J,K,M,N ⎞_x000D_ ⎝ ∅ ⎠⎝ a,c,e,g,i,k,m,o ⎠_x000D_ | M14: 0 | N14: 4.44 | O14: =ABS(D14-G14)/IF(D14=0,1,D14) -> 0 | P14: =ABS(D14-J14)/IF(D14=0,1,D14) -> 0 | Q14: =ABS(D14-M14)/IF(D14=0,1,D14) -> 0 | R14: =ROUND(IF(E14<H14, -(H14/IF(E14=0,1,E14)), IF(E14=0,1,E14)/IF(H14=0,1,H14)), 2) -> -0.03 | S14: =ROUND(IF(H14<K14, -(K14/IF(H14=0,1,H14)), IF(H14=0,1,H14)/IF(K14=0,1,K14)), 2) -> -458 | T14: =ROUND(IF(H14<N14, -(N14/IF(H14=0,1,H14)), IF(H14=0,1,H14)/IF(N14=0,1,N14)), 2) -> -148
A15: 13 | B15: ABCDEFGHIJKLMN_{t+1}|BDFHJLN_{t} | C15: KILLED | F15: ⎛ G ⎞⎛ A,B,C,D,E,F,H,I,J,K,L,M,N ⎞_x000D_ ⎝ ∅ ⎠⎝ b,d,f,h,j,l,n ⎠_x000D_ | G15: 0.01 | H15: 0.03 | I15: ⎛ G ⎞⎛ A,B,C,D,E,F,H,I,J,K,L,M,N ⎞_x000D_ ⎝ ∅ ⎠⎝ b,d,f,h,j,l,n ⎠_x000D_ | J15: 0.01 | K15: 13.56 | L15: ⎛ G ⎞⎛ A,B,C,D,E,F,H,I,J,K,L,M,N ⎞_x000D_ ⎝ ∅ ⎠⎝ b,d,f,h,j,l,n ⎠_x000D_ | M15: 0.01 | N15: 4.5 | O15: =ABS(D15-G15)/IF(D15=0,1,D15) -> 0.01 | P15: =ABS(D15-J15)/IF(D15=0,1,D15) -> 0.01 | Q15: =ABS(D15-M15)/IF(D15=0,1,D15) -> 0.01 | R15: =ROUND(IF(E15<H15, -(H15/IF(E15=0,1,E15)), IF(E15=0,1,E15)/IF(H15=0,1,H15)), 2) -> -0.03 | S15: =ROUND(IF(H15<K15, -(K15/IF(H15=0,1,H15)), IF(H15=0,1,H15)/IF(K15=0,1,K15)), 2) -> -452 | T15: =ROUND(IF(H15<N15, -(N15/IF(H15=0,1,H15)), IF(H15=0,1,H15)/IF(N15=0,1,N15)), 2) -> -150
A16: 14 | B16: ABCDEFGHIJKLMN_{t+1}|ABDEGHIJKLNO_{t} | C16: KILLED | F16: ⎛ N ⎞⎛ A,B,C,D,E,F,G,H,I,J,K,L,M ⎞_x000D_ ⎝ ∅ ⎠⎝ a,b,d,e,g,h,j,k,m,n ⎠_x000D_ | G16: 0 | H16: 0.14 | I16: ⎛ N ⎞⎛ A,B,C,D,E,F,G,H,I,J,K,L,M ⎞_x000D_ ⎝ ∅ ⎠⎝ a,b,d,e,g,h,j,k,m,n ⎠_x000D_ | J16: 0 | K16: 12.52 | L16: ⎛ N ⎞⎛ A,B,C,D,E,F,G,H,I,J,K,L,M ⎞_x000D_ ⎝ ∅ ⎠⎝ a,b,d,e,g,h,j,k,m,n ⎠_x000D_ | M16: 0 | N16: 4.26 | O16: =ABS(D16-G16)/IF(D16=0,1,D16) -> 0 | P16: =ABS(D16-J16)/IF(D16=0,1,D16) -> 0 | Q16: =ABS(D16-M16)/IF(D16=0,1,D16) -> 0 | R16: =ROUND(IF(E16<H16, -(H16/IF(E16=0,1,E16)), IF(E16=0,1,E16)/IF(H16=0,1,H16)), 2) -> -0.14 | S16: =ROUND(IF(H16<K16, -(K16/IF(H16=0,1,H16)), IF(H16=0,1,H16)/IF(K16=0,1,K16)), 2) -> -89.43 | T16: =ROUND(IF(H16<N16, -(N16/IF(H16=0,1,H16)), IF(H16=0,1,H16)/IF(N16=0,1,N16)), 2) -> -30.43
A17: 15 | B17: BCDEFGHIJKLMNO_{t+1}|ABCDEFGHIJKLMNO_{t} | C17: ⎛ ∅ ⎞⎛ B,C,D,E,F,G,H,I,J,K,L,M,N,O ⎞ ⎝ a ⎠⎝ b,c,d,e,f,g,h,i,j,k,l,m,n,o ⎠ | D17: 0 | E17: 11.79 | F17: ⎛ ∅ ⎞⎛ B,C,D,E,F,G,H,I,J,K,L,M,N,O ⎞_x000D_ ⎝ a ⎠⎝ b,c,d,e,f,g,h,i,j,k,l,m,n,o ⎠_x000D_ | G17: 0 | H17: 7.38 | I17: ⎛ ∅ ⎞⎛ B,C,D,E,F,G,H,I,J,K,L,M,N,O ⎞_x000D_ ⎝ a ⎠⎝ b,c,d,e,f,g,h,i,j,k,l,m,n,o ⎠_x000D_ | J17: 0 | K17: 18.71 | L17: ⎛ ∅ ⎞⎛ B,C,D,E,F,G,H,I,J,K,L,M,N,O ⎞_x000D_ ⎝ a ⎠⎝ b,c,d,e,f,g,h,i,j,k,l,m,n,o ⎠_x000D_ | M17: 0 | N17: 6.6 | O17: =ABS(D17-G17)/IF(D17=0,1,D17) -> 0 | P17: =ABS(D17-J17)/IF(D17=0,1,D17) -> 0 | Q17: =ABS(D17-M17)/IF(D17=0,1,D17) -> 0 | R17: =ROUND(IF(E17<H17, -(H17/IF(E17=0,1,E17)), IF(E17=0,1,E17)/IF(H17=0,1,H17)), 2) -> 1.6 | S17: =ROUND(IF(H17<K17, -(K17/IF(H17=0,1,H17)), IF(H17=0,1,H17)/IF(K17=0,1,K17)), 2) -> -2.54 | T17: =ROUND(IF(H17<N17, -(N17/IF(H17=0,1,H17)), IF(H17=0,1,H17)/IF(N17=0,1,N17)), 2) -> 1.12
A18: 16 | B18: BCDEFGHIJKLMNO_{t+1}|ABCDEFGHIJKLMN_{t} | C18: ⎛ ∅ ⎞⎛ B,C,D,E,F,G,H,I,J,K,L,M,N,O ⎞ ⎝ a ⎠⎝ b,c,d,e,f,g,h,i,j,k,l,m,n ⎠ | D18: 0 | E18: 11.98 | F18: ⎛ H ⎞⎛ B,C,D,E,F,G,I,J,K,L,M,N,O ⎞_x000D_ ⎝ ∅ ⎠⎝ a,b,c,d,e,f,g,h,i,j,k,l,m,n ⎠_x000D_ | G18: 0.03 | H18: 3.08 | I18: ⎛ H ⎞⎛ B,C,D,E,F,G,I,J,K,L,M,N,O ⎞_x000D_ ⎝ ∅ ⎠⎝ a,b,c,d,e,f,g,h,i,j,k,l,m,n ⎠_x000D_ | J18: 0.03 | K18: 15.78 | L18: ⎛ H ⎞⎛ B,C,D,E,F,G,I,J,K,L,M,N,O ⎞_x000D_ ⎝ ∅ ⎠⎝ a,b,c,d,e,f,g,h,i,j,k,l,m,n ⎠_x000D_ | M18: 0.03 | N18: 4.76 | O18: =ABS(D18-G18)/IF(D18=0,1,D18) -> 0.03 | P18: =ABS(D18-J18)/IF(D18=0,1,D18) -> 0.03 | Q18: =ABS(D18-M18)/IF(D18=0,1,D18) -> 0.03 | R18: =ROUND(IF(E18<H18, -(H18/IF(E18=0,1,E18)), IF(E18=0,1,E18)/IF(H18=0,1,H18)), 2) -> 3.89 | S18: =ROUND(IF(H18<K18, -(K18/IF(H18=0,1,H18)), IF(H18=0,1,H18)/IF(K18=0,1,K18)), 2) -> -5.12 | T18: =ROUND(IF(H18<N18, -(N18/IF(H18=0,1,H18)), IF(H18=0,1,H18)/IF(N18=0,1,N18)), 2) -> -1.55
A19: 17 | B19: BCDEFGHIJKLMNO_{t+1}|BCDEFGHIJKLMNO_{t} | C19: ⎛ ∅ ⎞⎛ B,C,D,E,F,G,H,I,J,K,L,M,N,O ⎞ ⎝ b ⎠⎝ c,d,e,f,g,h,i,j,k,l,m,n,o ⎠ | D19: 0 | E19: 12.71 | F19: ⎛ ∅ ⎞⎛ B,C,D,E,F,G,H,I,J,K,L,M,N,O ⎞_x000D_ ⎝ o ⎠⎝ b,c,d,e,f,g,h,i,j,k,l,m,n ⎠_x000D_ | G19: 0 | H19: 4.43 | I19: ⎛ ∅ ⎞⎛ B,C,D,E,F,G,H,I,J,K,L,M,N,O ⎞_x000D_ ⎝ o ⎠⎝ b,c,d,e,f,g,h,i,j,k,l,m,n ⎠_x000D_ | J19: 0 | K19: 14.96 | L19: ⎛ ∅ ⎞⎛ B,C,D,E,F,G,H,I,J,K,L,M,N,O ⎞_x000D_ ⎝ o ⎠⎝ b,c,d,e,f,g,h,i,j,k,l,m,n ⎠_x000D_ | M19: 0 | N19: 6.57 | O19: =ABS(D19-G19)/IF(D19=0,1,D19) -> 0 | P19: =ABS(D19-J19)/IF(D19=0,1,D19) -> 0 | Q19: =ABS(D19-M19)/IF(D19=0,1,D19) -> 0 | R19: =ROUND(IF(E19<H19, -(H19/IF(E19=0,1,E19)), IF(E19=0,1,E19)/IF(H19=0,1,H19)), 2) -> 2.87 | S19: =ROUND(IF(H19<K19, -(K19/IF(H19=0,1,H19)), IF(H19=0,1,H19)/IF(K19=0,1,K19)), 2) -> -3.38 | T19: =ROUND(IF(H19<N19, -(N19/IF(H19=0,1,H19)), IF(H19=0,1,H19)/IF(N19=0,1,N19)), 2) -> -1.48
A20: 18 | B20: BCDEFGHIJKLMNO_{t+1}|BCDEFGHIJKLMN_{t} | C20: ⎛ ∅ ⎞⎛ B,C,D,E,F,G,H,I,J,K,L,M,N,O ⎞ ⎝ b ⎠⎝ c,d,e,f,g,h,i,j,k,l,m,n ⎠ | D20: 0 | E20: 13.47 | F20: ⎛ H ⎞⎛ B,C,D,E,F,G,I,J,K,L,M,N,O ⎞_x000D_ ⎝ ∅ ⎠⎝ b,c,d,e,f,g,h,i,j,k,l,m,n ⎠_x000D_ | G20: 0.03 | H20: 1.42 | I20: ⎛ H ⎞⎛ B,C,D,E,F,G,I,J,K,L,M,N,O ⎞_x000D_ ⎝ ∅ ⎠⎝ b,c,d,e,f,g,h,i,j,k,l,m,n ⎠_x000D_ | J20: 0.03 | K20: 13.14 | L20: ⎛ H ⎞⎛ B,C,D,E,F,G,I,J,K,L,M,N,O ⎞_x000D_ ⎝ ∅ ⎠⎝ b,c,d,e,f,g,h,i,j,k,l,m,n ⎠_x000D_ | M20: 0.03 | N20: 4.51 | O20: =ABS(D20-G20)/IF(D20=0,1,D20) -> 0.03 | P20: =ABS(D20-J20)/IF(D20=0,1,D20) -> 0.03 | Q20: =ABS(D20-M20)/IF(D20=0,1,D20) -> 0.03 | R20: =ROUND(IF(E20<H20, -(H20/IF(E20=0,1,E20)), IF(E20=0,1,E20)/IF(H20=0,1,H20)), 2) -> 9.49 | S20: =ROUND(IF(H20<K20, -(K20/IF(H20=0,1,H20)), IF(H20=0,1,H20)/IF(K20=0,1,K20)), 2) -> -9.25 | T20: =ROUND(IF(H20<N20, -(N20/IF(H20=0,1,H20)), IF(H20=0,1,H20)/IF(N20=0,1,N20)), 2) -> -3.18
A21: 19 | B21: BCDEFGHIJKLMNO_{t+1}|ACEGIKMO_{t} | C21: KILLED | F21: ⎛ L ⎞⎛ B,C,D,E,F,G,H,I,J,K,M,N,O ⎞_x000D_ ⎝ ∅ ⎠⎝ a,c,e,g,i,k,m,o ⎠_x000D_ | G21: 0 | H21: 0.04 | I21: ⎛ L ⎞⎛ B,C,D,E,F,G,H,I,J,K,M,N,O ⎞_x000D_ ⎝ ∅ ⎠⎝ a,c,e,g,i,k,m,o ⎠_x000D_ | J21: 0 | K21: 12.93 | L21: ⎛ L ⎞⎛ B,C,D,E,F,G,H,I,J,K,M,N,O ⎞_x000D_ ⎝ ∅ ⎠⎝ a,c,e,g,i,k,m,o ⎠_x000D_ | M21: 0 | N21: 4.58 | O21: =ABS(D21-G21)/IF(D21=0,1,D21) -> 0 | P21: =ABS(D21-J21)/IF(D21=0,1,D21) -> 0 | Q21: =ABS(D21-M21)/IF(D21=0,1,D21) -> 0 | R21: =ROUND(IF(E21<H21, -(H21/IF(E21=0,1,E21)), IF(E21=0,1,E21)/IF(H21=0,1,H21)), 2) -> -0.04 | S21: =ROUND(IF(H21<K21, -(K21/IF(H21=0,1,H21)), IF(H21=0,1,H21)/IF(K21=0,1,K21)), 2) -> -323.25 | T21: =ROUND(IF(H21<N21, -(N21/IF(H21=0,1,H21)), IF(H21=0,1,H21)/IF(N21=0,1,N21)), 2) -> -114.5
A22: 20 | B22: BCDEFGHIJKLMNO_{t+1}|BDFHJLN_{t} | C22: KILLED | F22: ⎛ G ⎞⎛ B,C,D,E,F,H,I,J,K,L,M,N,O ⎞_x000D_ ⎝ ∅ ⎠⎝ b,d,f,h,j,l,n ⎠_x000D_ | G22: 0.01 | H22: 0.03 | I22: ⎛ G ⎞⎛ B,C,D,E,F,H,I,J,K,L,M,N,O ⎞_x000D_ ⎝ ∅ ⎠⎝ b,d,f,h,j,l,n ⎠_x000D_ | J22: 0.01 | K22: 12.19 | L22: ⎛ G ⎞⎛ B,C,D,E,F,H,I,J,K,L,M,N,O ⎞_x000D_ ⎝ ∅ ⎠⎝ b,d,f,h,j,l,n ⎠_x000D_ | M22: 0.01 | N22: 4.32 | O22: =ABS(D22-G22)/IF(D22=0,1,D22) -> 0.01 | P22: =ABS(D22-J22)/IF(D22=0,1,D22) -> 0.01 | Q22: =ABS(D22-M22)/IF(D22=0,1,D22) -> 0.01 | R22: =ROUND(IF(E22<H22, -(H22/IF(E22=0,1,E22)), IF(E22=0,1,E22)/IF(H22=0,1,H22)), 2) -> -0.03 | S22: =ROUND(IF(H22<K22, -(K22/IF(H22=0,1,H22)), IF(H22=0,1,H22)/IF(K22=0,1,K22)), 2) -> -406.33 | T22: =ROUND(IF(H22<N22, -(N22/IF(H22=0,1,H22)), IF(H22=0,1,H22)/IF(N22=0,1,N22)), 2) -> -144
A23: 21 | B23: BCDEFGHIJKLMNO_{t+1}|ABDEGHIJKLNO_{t} | C23: KILLED | F23: ⎛ O ⎞⎛ B,C,D,E,F,G,H,I,J,K,L,M,N ⎞_x000D_ ⎝ ∅ ⎠⎝ a,b,d,e,g,h,j,k,m,n ⎠_x000D_ | G23: 0 | H23: 0.14 | I23: ⎛ O ⎞⎛ B,C,D,E,F,G,H,I,J,K,L,M,N ⎞_x000D_ ⎝ ∅ ⎠⎝ a,b,d,e,g,h,j,k,m,n ⎠_x000D_ | J23: 0 | K23: 11.03 | L23: ⎛ O ⎞⎛ B,C,D,E,F,G,H,I,J,K,L,M,N ⎞_x000D_ ⎝ ∅ ⎠⎝ a,b,d,e,g,h,j,k,m,n ⎠_x000D_ | M23: 0 | N23: 4.62 | O23: =ABS(D23-G23)/IF(D23=0,1,D23) -> 0 | P23: =ABS(D23-J23)/IF(D23=0,1,D23) -> 0 | Q23: =ABS(D23-M23)/IF(D23=0,1,D23) -> 0 | R23: =ROUND(IF(E23<H23, -(H23/IF(E23=0,1,E23)), IF(E23=0,1,E23)/IF(H23=0,1,H23)), 2) -> -0.14 | S23: =ROUND(IF(H23<K23, -(K23/IF(H23=0,1,H23)), IF(H23=0,1,H23)/IF(K23=0,1,K23)), 2) -> -78.79 | T23: =ROUND(IF(H23<N23, -(N23/IF(H23=0,1,H23)), IF(H23=0,1,H23)/IF(N23=0,1,N23)), 2) -> -33
A24: 22 | B24: BCDEFGHIJKLMN_{t+1}|ABCDEFGHIJKLMNO_{t} | C24: ⎛ ∅ ⎞⎛ B,C,D,E,F,G,H,I,J,K,L,M,N ⎞ ⎝ a ⎠⎝ b,c,d,e,f,g,h,i,j,k,l,m,n,o ⎠ | D24: 0 | E24: 4.65 | F24: ⎛ ∅ ⎞⎛ B,C,D,E,F,G,H,I,J,K,L,M,N ⎞_x000D_ ⎝ a ⎠⎝ b,c,d,e,f,g,h,i,j,k,l,m,n,o ⎠_x000D_ | G24: 0 | H24: 7.05 | I24: ⎛ ∅ ⎞⎛ B,C,D,E,F,G,H,I,J,K,L,M,N ⎞_x000D_ ⎝ a ⎠⎝ b,c,d,e,f,g,h,i,j,k,l,m,n,o ⎠_x000D_ | J24: 0 | K24: 14.99 | L24: ⎛ ∅ ⎞⎛ B,C,D,E,F,G,H,I,J,K,L,M,N ⎞_x000D_ ⎝ a ⎠⎝ b,c,d,e,f,g,h,i,j,k,l,m,n,o ⎠_x000D_ | M24: 0 | N24: 6.31 | O24: =ABS(D24-G24)/IF(D24=0,1,D24) -> 0 | P24: =ABS(D24-J24)/IF(D24=0,1,D24) -> 0 | Q24: =ABS(D24-M24)/IF(D24=0,1,D24) -> 0 | R24: =ROUND(IF(E24<H24, -(H24/IF(E24=0,1,E24)), IF(E24=0,1,E24)/IF(H24=0,1,H24)), 2) -> -1.52 | S24: =ROUND(IF(H24<K24, -(K24/IF(H24=0,1,H24)), IF(H24=0,1,H24)/IF(K24=0,1,K24)), 2) -> -2.13 | T24: =ROUND(IF(H24<N24, -(N24/IF(H24=0,1,H24)), IF(H24=0,1,H24)/IF(N24=0,1,N24)), 2) -> 1.12
A25: 23 | B25: BCDEFGHIJKLMN_{t+1}|ABCDEFGHIJKLMN_{t} | C25: ⎛ ∅ ⎞⎛ B,C,D,E,F,G,H,I,J,K,L,M,N ⎞ ⎝ a ⎠⎝ b,c,d,e,f,g,h,i,j,k,l,m,n ⎠ | D25: 0 | E25: 4.62 | F25: ⎛ H ⎞⎛ B,C,D,E,F,G,I,J,K,L,M,N ⎞_x000D_ ⎝ ∅ ⎠⎝ a,b,c,d,e,f,g,h,i,j,k,l,m,n ⎠_x000D_ | G25: 0.03 | H25: 2.82 | I25: ⎛ H ⎞⎛ B,C,D,E,F,G,I,J,K,L,M,N ⎞_x000D_ ⎝ ∅ ⎠⎝ a,b,c,d,e,f,g,h,i,j,k,l,m,n ⎠_x000D_ | J25: 0.03 | K25: 13.35 | L25: ⎛ H ⎞⎛ B,C,D,E,F,G,I,J,K,L,M,N ⎞_x000D_ ⎝ ∅ ⎠⎝ a,b,c,d,e,f,g,h,i,j,k,l,m,n ⎠_x000D_ | M25: 0.03 | N25: 4.64 | O25: =ABS(D25-G25)/IF(D25=0,1,D25) -> 0.03 | P25: =ABS(D25-J25)/IF(D25=0,1,D25) -> 0.03 | Q25: =ABS(D25-M25)/IF(D25=0,1,D25) -> 0.03 | R25: =ROUND(IF(E25<H25, -(H25/IF(E25=0,1,E25)), IF(E25=0,1,E25)/IF(H25=0,1,H25)), 2) -> 1.64 | S25: =ROUND(IF(H25<K25, -(K25/IF(H25=0,1,H25)), IF(H25=0,1,H25)/IF(K25=0,1,K25)), 2) -> -4.73 | T25: =ROUND(IF(H25<N25, -(N25/IF(H25=0,1,H25)), IF(H25=0,1,H25)/IF(N25=0,1,N25)), 2) -> -1.65
A26: 24 | B26: BCDEFGHIJKLMN_{t+1}|BCDEFGHIJKLMNO_{t} | C26: ⎛ ∅ ⎞⎛ B,C,D,E,F,G,H,I,J,K,L,M,N ⎞ ⎝ b ⎠⎝ c,d,e,f,g,h,i,j,k,l,m,n,o ⎠ | D26: 0 | E26: 4.73 | F26: ⎛ ∅ ⎞⎛ B,C,D,E,F,G,H,I,J,K,L,M,N ⎞_x000D_ ⎝ o ⎠⎝ b,c,d,e,f,g,h,i,j,k,l,m,n ⎠_x000D_ | G26: 0 | H26: 3.92 | I26: ⎛ ∅ ⎞⎛ B,C,D,E,F,G,H,I,J,K,L,M,N ⎞_x000D_ ⎝ o ⎠⎝ b,c,d,e,f,g,h,i,j,k,l,m,n ⎠_x000D_ | J26: 0 | K26: 13.11 | L26: ⎛ ∅ ⎞⎛ B,C,D,E,F,G,H,I,J,K,L,M,N ⎞_x000D_ ⎝ o ⎠⎝ b,c,d,e,f,g,h,i,j,k,l,m,n ⎠_x000D_ | M26: 0 | N26: 6.26 | O26: =ABS(D26-G26)/IF(D26=0,1,D26) -> 0 | P26: =ABS(D26-J26)/IF(D26=0,1,D26) -> 0 | Q26: =ABS(D26-M26)/IF(D26=0,1,D26) -> 0 | R26: =ROUND(IF(E26<H26, -(H26/IF(E26=0,1,E26)), IF(E26=0,1,E26)/IF(H26=0,1,H26)), 2) -> 1.21 | S26: =ROUND(IF(H26<K26, -(K26/IF(H26=0,1,H26)), IF(H26=0,1,H26)/IF(K26=0,1,K26)), 2) -> -3.34 | T26: =ROUND(IF(H26<N26, -(N26/IF(H26=0,1,H26)), IF(H26=0,1,H26)/IF(N26=0,1,N26)), 2) -> -1.6
A27: 25 | B27: BCDEFGHIJKLMN_{t+1}|BCDEFGHIJKLMN_{t} | C27: ⎛ ∅ ⎞⎛ B,C,D,E,F,G,H,I,J,K,L,M,N ⎞ ⎝ b ⎠⎝ c,d,e,f,g,h,i,j,k,l,m,n ⎠ | D27: 0 | E27: 4.67 | F27: ⎛ H ⎞⎛ B,C,D,E,F,G,I,J,K,L,M,N ⎞_x000D_ ⎝ ∅ ⎠⎝ b,c,d,e,f,g,h,i,j,k,l,m,n ⎠_x000D_ | G27: 0.03 | H27: 1.29 | I27: ⎛ H ⎞⎛ B,C,D,E,F,G,I,J,K,L,M,N ⎞_x000D_ ⎝ ∅ ⎠⎝ b,c,d,e,f,g,h,i,j,k,l,m,n ⎠_x000D_ | J27: 0.03 | K27: 11.42 | L27: ⎛ H ⎞⎛ B,C,D,E,F,G,I,J,K,L,M,N ⎞_x000D_ ⎝ ∅ ⎠⎝ b,c,d,e,f,g,h,i,j,k,l,m,n ⎠_x000D_ | M27: 0.03 | N27: 4.67 | O27: =ABS(D27-G27)/IF(D27=0,1,D27) -> 0.03 | P27: =ABS(D27-J27)/IF(D27=0,1,D27) -> 0.03 | Q27: =ABS(D27-M27)/IF(D27=0,1,D27) -> 0.03 | R27: =ROUND(IF(E27<H27, -(H27/IF(E27=0,1,E27)), IF(E27=0,1,E27)/IF(H27=0,1,H27)), 2) -> 3.62 | S27: =ROUND(IF(H27<K27, -(K27/IF(H27=0,1,H27)), IF(H27=0,1,H27)/IF(K27=0,1,K27)), 2) -> -8.85 | T27: =ROUND(IF(H27<N27, -(N27/IF(H27=0,1,H27)), IF(H27=0,1,H27)/IF(N27=0,1,N27)), 2) -> -3.62
A28: 26 | B28: BCDEFGHIJKLMN_{t+1}|ACEGIKMO_{t} | C28: KILLED | F28: ⎛ L ⎞⎛ B,C,D,E,F,G,H,I,J,K,M,N ⎞_x000D_ ⎝ ∅ ⎠⎝ a,c,e,g,i,k,m,o ⎠_x000D_ | G28: 0 | H28: 0.03 | I28: ⎛ L ⎞⎛ B,C,D,E,F,G,H,I,J,K,M,N ⎞_x000D_ ⎝ ∅ ⎠⎝ a,c,e,g,i,k,m,o ⎠_x000D_ | J28: 0 | K28: 11.15 | L28: ⎛ L ⎞⎛ B,C,D,E,F,G,H,I,J,K,M,N ⎞_x000D_ ⎝ ∅ ⎠⎝ a,c,e,g,i,k,m,o ⎠_x000D_ | M28: 0 | N28: 4.34 | O28: =ABS(D28-G28)/IF(D28=0,1,D28) -> 0 | P28: =ABS(D28-J28)/IF(D28=0,1,D28) -> 0 | Q28: =ABS(D28-M28)/IF(D28=0,1,D28) -> 0 | R28: =ROUND(IF(E28<H28, -(H28/IF(E28=0,1,E28)), IF(E28=0,1,E28)/IF(H28=0,1,H28)), 2) -> -0.03 | S28: =ROUND(IF(H28<K28, -(K28/IF(H28=0,1,H28)), IF(H28=0,1,H28)/IF(K28=0,1,K28)), 2) -> -371.67 | T28: =ROUND(IF(H28<N28, -(N28/IF(H28=0,1,H28)), IF(H28=0,1,H28)/IF(N28=0,1,N28)), 2) -> -144.67
A29: 27 | B29: BCDEFGHIJKLMN_{t+1}|BDFHJLN_{t} | C29: KILLED | F29: ⎛ G ⎞⎛ B,C,D,E,F,H,I,J,K,L,M,N ⎞_x000D_ ⎝ ∅ ⎠⎝ b,d,f,h,j,l,n ⎠_x000D_ | G29: 0.01 | H29: 0.02 | I29: ⎛ G ⎞⎛ B,C,D,E,F,H,I,J,K,L,M,N ⎞_x000D_ ⎝ ∅ ⎠⎝ b,d,f,h,j,l,n ⎠_x000D_ | J29: 0.01 | K29: 11.06 | L29: ⎛ G ⎞⎛ B,C,D,E,F,H,I,J,K,L,M,N ⎞_x000D_ ⎝ ∅ ⎠⎝ b,d,f,h,j,l,n ⎠_x000D_ | M29: 0.01 | N29: 4.33 | O29: =ABS(D29-G29)/IF(D29=0,1,D29) -> 0.01 | P29: =ABS(D29-J29)/IF(D29=0,1,D29) -> 0.01 | Q29: =ABS(D29-M29)/IF(D29=0,1,D29) -> 0.01 | R29: =ROUND(IF(E29<H29, -(H29/IF(E29=0,1,E29)), IF(E29=0,1,E29)/IF(H29=0,1,H29)), 2) -> -0.02 | S29: =ROUND(IF(H29<K29, -(K29/IF(H29=0,1,H29)), IF(H29=0,1,H29)/IF(K29=0,1,K29)), 2) -> -553 | T29: =ROUND(IF(H29<N29, -(N29/IF(H29=0,1,H29)), IF(H29=0,1,H29)/IF(N29=0,1,N29)), 2) -> -216.5
A30: 28 | B30: BCDEFGHIJKLMN_{t+1}|ABDEGHIJKLNO_{t} | C30: KILLED | F30: ⎛ N ⎞⎛ B,C,D,E,F,G,H,I,J,K,L,M ⎞_x000D_ ⎝ ∅ ⎠⎝ a,b,d,e,g,h,j,k,m,n ⎠_x000D_ | G30: 0 | H30: 0.14 | I30: ⎛ N ⎞⎛ B,C,D,E,F,G,H,I,J,K,L,M ⎞_x000D_ ⎝ ∅ ⎠⎝ a,b,d,e,g,h,j,k,m,n ⎠_x000D_ | J30: 0 | K30: 11.08 | L30: ⎛ N ⎞⎛ B,C,D,E,F,G,H,I,J,K,L,M ⎞_x000D_ ⎝ ∅ ⎠⎝ a,b,d,e,g,h,j,k,m,n ⎠_x000D_ | M30: 0 | N30: 4.65 | O30: =ABS(D30-G30)/IF(D30=0,1,D30) -> 0 | P30: =ABS(D30-J30)/IF(D30=0,1,D30) -> 0 | Q30: =ABS(D30-M30)/IF(D30=0,1,D30) -> 0 | R30: =ROUND(IF(E30<H30, -(H30/IF(E30=0,1,E30)), IF(E30=0,1,E30)/IF(H30=0,1,H30)), 2) -> -0.14 | S30: =ROUND(IF(H30<K30, -(K30/IF(H30=0,1,H30)), IF(H30=0,1,H30)/IF(K30=0,1,K30)), 2) -> -79.14 | T30: =ROUND(IF(H30<N30, -(N30/IF(H30=0,1,H30)), IF(H30=0,1,H30)/IF(N30=0,1,N30)), 2) -> -33.21
A31: 29 | B31: ACEGIKMO_{t+1}|ABCDEFGHIJKLMNO_{t} | C31: ⎛ ∅ ⎞⎛ A,C,E,G,I,K,M,O ⎞ ⎝ a ⎠⎝ b,c,d,e,f,g,h,i,j,k,l,m,n,o ⎠ | D31: 0 | E31: 0.56 | F31: ⎛ ∅ ⎞⎛ A,C,E,G,I,K,M,O ⎞_x000D_ ⎝ a ⎠⎝ b,c,d,e,f,g,h,i,j,k,l,m,n,o ⎠_x000D_ | G31: 0 | H31: 3.97 | I31: ⎛ ∅ ⎞⎛ A,C,E,G,I,K,M,O ⎞_x000D_ ⎝ a ⎠⎝ b,c,d,e,f,g,h,i,j,k,l,m,n,o ⎠_x000D_ | J31: 0 | K31: 13.05 | L31: ⎛ ∅ ⎞⎛ A,C,E,G,I,K,M,O ⎞_x000D_ ⎝ a ⎠⎝ b,c,d,e,f,g,h,i,j,k,l,m,n,o ⎠_x000D_ | M31: 0 | N31: 5.17 | O31: =ABS(D31-G31)/IF(D31=0,1,D31) -> 0 | P31: =ABS(D31-J31)/IF(D31=0,1,D31) -> 0 | Q31: =ABS(D31-M31)/IF(D31=0,1,D31) -> 0 | R31: =ROUND(IF(E31<H31, -(H31/IF(E31=0,1,E31)), IF(E31=0,1,E31)/IF(H31=0,1,H31)), 2) -> -7.09 | S31: =ROUND(IF(H31<K31, -(K31/IF(H31=0,1,H31)), IF(H31=0,1,H31)/IF(K31=0,1,K31)), 2) -> -3.29 | T31: =ROUND(IF(H31<N31, -(N31/IF(H31=0,1,H31)), IF(H31=0,1,H31)/IF(N31=0,1,N31)), 2) -> -1.3
A32: 30 | B32: ACEGIKMO_{t+1}|ABCDEFGHIJKLMN_{t} | C32: ⎛ ∅ ⎞⎛ A,C,E,G,I,K,M,O ⎞ ⎝ a ⎠⎝ b,c,d,e,f,g,h,i,j,k,l,m,n ⎠ | D32: 0 | E32: 0.5 | F32: ⎛ G ⎞⎛ A,C,E,I,K,M,O ⎞_x000D_ ⎝ ∅ ⎠⎝ a,b,c,d,e,f,g,h,i,j,k,l,m,n ⎠_x000D_ | G32: 0.03 | H32: 1.72 | I32: ⎛ G ⎞⎛ A,C,E,I,K,M,O ⎞_x000D_ ⎝ ∅ ⎠⎝ a,b,c,d,e,f,g,h,i,j,k,l,m,n ⎠_x000D_ | J32: 0.03 | K32: 11.73 | L32: ⎛ G ⎞⎛ A,C,E,I,K,M,O ⎞_x000D_ ⎝ ∅ ⎠⎝ a,b,c,d,e,f,g,h,i,j,k,l,m,n ⎠_x000D_ | M32: 0.03 | N32: 4.34 | O32: =ABS(D32-G32)/IF(D32=0,1,D32) -> 0.03 | P32: =ABS(D32-J32)/IF(D32=0,1,D32) -> 0.03 | Q32: =ABS(D32-M32)/IF(D32=0,1,D32) -> 0.03 | R32: =ROUND(IF(E32<H32, -(H32/IF(E32=0,1,E32)), IF(E32=0,1,E32)/IF(H32=0,1,H32)), 2) -> -3.44 | S32: =ROUND(IF(H32<K32, -(K32/IF(H32=0,1,H32)), IF(H32=0,1,H32)/IF(K32=0,1,K32)), 2) -> -6.82 | T32: =ROUND(IF(H32<N32, -(N32/IF(H32=0,1,H32)), IF(H32=0,1,H32)/IF(N32=0,1,N32)), 2) -> -2.52
A33: 31 | B33: ACEGIKMO_{t+1}|BCDEFGHIJKLMNO_{t} | C33: ⎛ ∅ ⎞⎛ A,C,E,G,I,K,M,O ⎞ ⎝ b ⎠⎝ c,d,e,f,g,h,i,j,k,l,m,n,o ⎠ | D33: 0 | E33: 0.5 | F33: ⎛ ∅ ⎞⎛ A,C,E,G,I,K,M,O ⎞_x000D_ ⎝ o ⎠⎝ b,c,d,e,f,g,h,i,j,k,l,m,n ⎠_x000D_ | G33: 0 | H33: 2.53 | I33: ⎛ ∅ ⎞⎛ A,C,E,G,I,K,M,O ⎞_x000D_ ⎝ o ⎠⎝ b,c,d,e,f,g,h,i,j,k,l,m,n ⎠_x000D_ | J33: 0 | K33: 12.69 | L33: ⎛ ∅ ⎞⎛ A,C,E,G,I,K,M,O ⎞_x000D_ ⎝ o ⎠⎝ b,c,d,e,f,g,h,i,j,k,l,m,n ⎠_x000D_ | M33: 0 | N33: 5.35 | O33: =ABS(D33-G33)/IF(D33=0,1,D33) -> 0 | P33: =ABS(D33-J33)/IF(D33=0,1,D33) -> 0 | Q33: =ABS(D33-M33)/IF(D33=0,1,D33) -> 0 | R33: =ROUND(IF(E33<H33, -(H33/IF(E33=0,1,E33)), IF(E33=0,1,E33)/IF(H33=0,1,H33)), 2) -> -5.06 | S33: =ROUND(IF(H33<K33, -(K33/IF(H33=0,1,H33)), IF(H33=0,1,H33)/IF(K33=0,1,K33)), 2) -> -5.02 | T33: =ROUND(IF(H33<N33, -(N33/IF(H33=0,1,H33)), IF(H33=0,1,H33)/IF(N33=0,1,N33)), 2) -> -2.11
A34: 32 | B34: ACEGIKMO_{t+1}|BCDEFGHIJKLMN_{t} | C34: ⎛ ∅ ⎞⎛ A,C,E,G,I,K,M,O ⎞ ⎝ b ⎠⎝ c,d,e,f,g,h,i,j,k,l,m,n ⎠ | D34: 0 | E34: 0.51 | F34: ⎛ G ⎞⎛ A,C,E,I,K,M,O ⎞_x000D_ ⎝ ∅ ⎠⎝ b,c,d,e,f,g,h,i,j,k,l,m,n ⎠_x000D_ | G34: 0.03 | H34: 0.8 | I34: ⎛ G ⎞⎛ A,C,E,I,K,M,O ⎞_x000D_ ⎝ ∅ ⎠⎝ b,c,d,e,f,g,h,i,j,k,l,m,n ⎠_x000D_ | J34: 0.03 | K34: 11.22 | L34: ⎛ G ⎞⎛ A,C,E,I,K,M,O ⎞_x000D_ ⎝ ∅ ⎠⎝ b,c,d,e,f,g,h,i,j,k,l,m,n ⎠_x000D_ | M34: 0.03 | N34: 4.4 | O34: =ABS(D34-G34)/IF(D34=0,1,D34) -> 0.03 | P34: =ABS(D34-J34)/IF(D34=0,1,D34) -> 0.03 | Q34: =ABS(D34-M34)/IF(D34=0,1,D34) -> 0.03 | R34: =ROUND(IF(E34<H34, -(H34/IF(E34=0,1,E34)), IF(E34=0,1,E34)/IF(H34=0,1,H34)), 2) -> -1.57 | S34: =ROUND(IF(H34<K34, -(K34/IF(H34=0,1,H34)), IF(H34=0,1,H34)/IF(K34=0,1,K34)), 2) -> -14.03 | T34: =ROUND(IF(H34<N34, -(N34/IF(H34=0,1,H34)), IF(H34=0,1,H34)/IF(N34=0,1,N34)), 2) -> -5.5
A35: 33 | B35: ACEGIKMO_{t+1}|ACEGIKMO_{t} | C35: ⎛ E ⎞⎛ A,C,G,I,K,M,O ⎞ ⎝ ∅ ⎠⎝ a,c,e,g,i,k,m,o ⎠ | D35: 0 | E35: 8.67 | F35: ⎛ E ⎞⎛ A,C,G,I,K,M,O ⎞_x000D_ ⎝ ∅ ⎠⎝ a,c,e,g,i,k,m,o ⎠_x000D_ | G35: 0 | H35: 0.02 | I35: ⎛ E ⎞⎛ A,C,G,I,K,M,O ⎞_x000D_ ⎝ ∅ ⎠⎝ a,c,e,g,i,k,m,o ⎠_x000D_ | J35: 0 | K35: 11.02 | L35: ⎛ E ⎞⎛ A,C,G,I,K,M,O ⎞_x000D_ ⎝ ∅ ⎠⎝ a,c,e,g,i,k,m,o ⎠_x000D_ | M35: 0 | N35: 4.23 | O35: =ABS(D35-G35)/IF(D35=0,1,D35) -> 0 | P35: =ABS(D35-J35)/IF(D35=0,1,D35) -> 0 | Q35: =ABS(D35-M35)/IF(D35=0,1,D35) -> 0 | R35: =ROUND(IF(E35<H35, -(H35/IF(E35=0,1,E35)), IF(E35=0,1,E35)/IF(H35=0,1,H35)), 2) -> 433.5 | S35: =ROUND(IF(H35<K35, -(K35/IF(H35=0,1,H35)), IF(H35=0,1,H35)/IF(K35=0,1,K35)), 2) -> -551 | T35: =ROUND(IF(H35<N35, -(N35/IF(H35=0,1,H35)), IF(H35=0,1,H35)/IF(N35=0,1,N35)), 2) -> -211.5
A36: 34 | B36: ACEGIKMO_{t+1}|BDFHJLN_{t} | C36: ⎛ G ⎞⎛ A,C,E,I,K,M,O ⎞ ⎝ ∅ ⎠⎝ b,d,f,h,j,l,n ⎠ | D36: 0 | E36: 4.55 | F36: ⎛ G ⎞⎛ A,C,E,I,K,M,O ⎞_x000D_ ⎝ ∅ ⎠⎝ b,d,f,h,j,l,n ⎠_x000D_ | G36: 0.01 | H36: 0.02 | I36: ⎛ G ⎞⎛ A,C,E,I,K,M,O ⎞_x000D_ ⎝ ∅ ⎠⎝ b,d,f,h,j,l,n ⎠_x000D_ | J36: 0.01 | K36: 10.97 | L36: ⎛ G ⎞⎛ A,C,E,I,K,M,O ⎞_x000D_ ⎝ ∅ ⎠⎝ b,d,f,h,j,l,n ⎠_x000D_ | M36: 0.01 | N36: 4.42 | O36: =ABS(D36-G36)/IF(D36=0,1,D36) -> 0.01 | P36: =ABS(D36-J36)/IF(D36=0,1,D36) -> 0.01 | Q36: =ABS(D36-M36)/IF(D36=0,1,D36) -> 0.01 | R36: =ROUND(IF(E36<H36, -(H36/IF(E36=0,1,E36)), IF(E36=0,1,E36)/IF(H36=0,1,H36)), 2) -> 227.5 | S36: =ROUND(IF(H36<K36, -(K36/IF(H36=0,1,H36)), IF(H36=0,1,H36)/IF(K36=0,1,K36)), 2) -> -548.5 | T36: =ROUND(IF(H36<N36, -(N36/IF(H36=0,1,H36)), IF(H36=0,1,H36)/IF(N36=0,1,N36)), 2) -> -221
A37: 35 | B37: ACEGIKMO_{t+1}|ABDEGHIJKLNO_{t} | C37: ⎛ O ⎞⎛ A,C,E,G,I,K,M ⎞ ⎝ ∅ ⎠⎝ a,b,d,e,g,h,j,k,m,n ⎠ | D37: 0 | E37: 33.44 | F37: ⎛ O ⎞⎛ A,C,E,G,I,K,M ⎞_x000D_ ⎝ ∅ ⎠⎝ a,b,d,e,g,h,j,k,m,n ⎠_x000D_ | G37: 0 | H37: 0.12 | I37: ⎛ O ⎞⎛ A,C,E,G,I,K,M ⎞_x000D_ ⎝ ∅ ⎠⎝ a,b,d,e,g,h,j,k,m,n ⎠_x000D_ | J37: 0 | K37: 11.02 | L37: ⎛ O ⎞⎛ A,C,E,G,I,K,M ⎞_x000D_ ⎝ ∅ ⎠⎝ a,b,d,e,g,h,j,k,m,n ⎠_x000D_ | M37: 0 | N37: 4.16 | O37: =ABS(D37-G37)/IF(D37=0,1,D37) -> 0 | P37: =ABS(D37-J37)/IF(D37=0,1,D37) -> 0 | Q37: =ABS(D37-M37)/IF(D37=0,1,D37) -> 0 | R37: =ROUND(IF(E37<H37, -(H37/IF(E37=0,1,E37)), IF(E37=0,1,E37)/IF(H37=0,1,H37)), 2) -> 278.67 | S37: =ROUND(IF(H37<K37, -(K37/IF(H37=0,1,H37)), IF(H37=0,1,H37)/IF(K37=0,1,K37)), 2) -> -91.83 | T37: =ROUND(IF(H37<N37, -(N37/IF(H37=0,1,H37)), IF(H37=0,1,H37)/IF(N37=0,1,N37)), 2) -> -34.67
